Workbook

Sheet Sheet1
AE1: 30 | AF1: 复位开关 | AG1: 1 | AK1: 障碍物X | AL1: 障碍物Y | AM1: =OFFSET(Sheet3!$A$1, 30-$AH$5, $AG$5-1) -> 99999 | AN1: =OFFSET(Sheet3!$A$1, 30-$AH$5, $AG$5) -> 4777.5113 | AO1: =OFFSET(Sheet3!$A$1, 30-$AH$5, $AG$5+1) -> 6234.2645 | AQ1: 引力权重(α) | AR1: 1
AE2: 29 | AF2: 步数 | AG2: =IF($AG$1=1, 0, $AG$2+1) -> 0 | AK2: 1 | AL2: 30 | AM2: =OFFSET(Sheet3!$A$1, 31-$AH$5, $AG$5-1) -> 99999 | AN2: =OFFSET(Sheet3!$A$1, 31-$AH$5, $AG$5) -> 4326.0091 | AO2: =OFFSET(Sheet3!$A$1, 31-$AH$5, $AG$5+1) -> 5119.4068 | AP2: =MIN(AM1:AO1, AM2, AO2, AM3:AO3) -> 4777.5113 | AQ2: 斥力权重(β) | AR2: 10000
AE3: 28 | AF3: 1 | AG3: 1 | AK3: 30 | AL3: 1 | AM3: =OFFSET(Sheet3!$A$1, 32-$AH$5, $AG$5-1) -> 99999 | AN3: =OFFSET(Sheet3!$A$1, 32-$AH$5, $AG$5) -> 99999 | AO3: =OFFSET(Sheet3!$A$1, 32-$AH$5, $AG$5+1) -> 99999
AE4: 27 | AF4: 30 | AG4: 30 | AK4: 25 | AL4: 7
AE5: 26 | AF5: 机器人坐标 | AG5: =IF($AG$1=1, $AF$3, IF(OR($AN$2=0, $AP$2>=99999), $AG$5, IF(OR($AM$1=$AP$2, $AM$2=$AP$2, $AM$3=$AP$2), $AG$5-1, IF(OR($AO$1=$AP$2, $AO$2=$AP$2, $AO$3=$AP$2), $AG$5+1, $AG$5)))) -> 1 | AH5: =IF($AG$1=1, $AG$3, IF(OR($AN$2=0, $AP$2>=99999), $AH$5, IF(OR($AM$1=$AP$2, $AN$1=$AP$2, $AO$1=$AP$2), $AH$5+1, IF(OR($AM$3=$AP$2, $AN$3=$AP$2, $AO$3=$AP$2), $AH$5-1, $AH$5)))) -> 1 | AK5: 6 | AL5: 3
AE6: 25 | AK6: 7 | AL6: 6
AE7: 24 | AK7: 5 | AL7: 5
AE8: 23 | AK8: 8 | AL8: 8
AE9: 22 | AK9: 4 | AL9: 3
AE10: 21 | AK10: 6 | AL10: 7
AE11: 20 | AK11: 6 | AL11: 9
AE12: 19 | AK12: 7 | AL12: 23
AE13: 18 | AK13: 7 | AL13: 24
AE14: 17 | AK14: 6 | AL14: 14
AE15: 16 | AK15: 5 | AL15: 13
AE16: 15 | AK16: 3 | AL16: 24
AE17: 14 | AK17: 29 | AL17: 15
... AE30: 1 | AK30: 17 | AL30: 8
A31: 1 | B31: 2 | C31: 3 | D31: 4 | E31: 5 | F31: 6 | G31: 7 | H31: 8 | I31: 9 | J31: 10 | K31: 11 | L31: 12 | M31: 13 | N31: 14 | O31: 15 | P31: 16 | Q31: 17 | R31: 18 | S31: 19 | T31: 20 | U31: 21 | V31: 22 | W31: 23 | X31: 24 | Y31: 25 | Z31: 26 | AA31: 27 | AB31: 28 | AC31: 29 | AD31: 30 | AK31: 18 | AL31: 9
AK32: 19 | AL32: 10
AK33: 8 | AL33: 17
AK34: 9 | AL34: 18
AK35: 10 | AL35: 19
AK36: 18 | AL36: 20
AK37: 19 | AL37: 19
AK38: 20 | AL38: 18

Sheet Sheet2
A1: 999 | B1: 999 | C1: 999 | D1: 999 | E1: 999 | F1: 999 | G1: 999 | H1: 999 | I1: 999 | J1: 999 | K1: 999 | L1: 999 | M1: 999 | N1: 999 | O1: 999 | P1: 999 | Q1: 999 | R1: 999 | S1: 999 | T1: 999 | U1: 999 | V1: 999 | W1: 999 | X1: 999 | Y1: 999 | Z1: 999 | AA1: 999 | AB1: 999 | AC1: 999 | AD1: 999 | AE1: 999 | AF1: 999
A2: 999 | B2: =IF(Sheet1!$AG$1=1, IF(AND(COLUMN()-1=Sheet1!$AF$4, 32-ROW()=Sheet1!$AG$4), 0, 999), IF(COUNTIFS(Sheet1!$AK$1:$AK$50, COLUMN()-1, Sheet1!$AL$1:$AL$50, 32-ROW())>0, 999, IF(AND(COLUMN()-1=Sheet1!$AF$4, 32-ROW()=Sheet1!$AG$4), 0, MIN(A1, B1, C1, A2, C2, A3, B3, C3) + 1))) -> 999 | C2: =IF(Sheet1!$AG$1=1, IF(AND(COLUMN()-1=Sheet1!$AF$4, 32-ROW()=Sheet1!$AG$4), 0, 999), IF(COUNTIFS(Sheet1!$AK$1:$AK$50, COLUMN()-1, Sheet1!$AL$1:$AL$50, 32-ROW())>0, 999, IF(AND(COLUMN()-1=Sheet1!$AF$4, 32-ROW()=Sheet1!$AG$4), 0, MIN(B1, C1, D1, B2, D2, B3, C3, D3) + 1))) -> 999 | D2: =IF(Sheet1!$AG$1=1, IF(AND(COLUMN()-1=Sheet1!$AF$4, 32-ROW()=Sheet1!$AG$4), 0, 999), IF(COUNTIFS(Sheet1!$AK$1:$AK$50, COLUMN()-1, Sheet1!$AL$1:$AL$50, 32-ROW())>0, 999, IF(AND(COLUMN()-1=Sheet1!$AF$4, 32-ROW()=Sheet1!$AG$4), 0, MIN(C1, D1, E1, C2, E2, C3, D3, E3) + 1))) -> 999 | E2: =IF(Sheet1!$AG$1=1, IF(AND(COLUMN()-1=Sheet1!$AF$4, 32-ROW()=Sheet1!$AG$4), 0, 999), IF(COUNTIFS(Sheet1!$AK$1:$AK$50, COLUMN()-1, Sheet1!$AL$1:$AL$50, 32-ROW())>0, 999, IF(AND(COLUMN()-1=Sheet1!$AF$4, 32-ROW()=Sheet1!$AG$4), 0, MIN(D1, E1, F1, D2, F2, D3, E3, F3) + 1))) -> 999 | F2: =IF(Sheet1!$AG$1=1, IF(AND(COLUMN()-1=Sheet1!$AF$4, 32-ROW()=Sheet1!$AG$4), 0, 999), IF(COUNTIFS(Sheet1!$AK$1:$AK$50, COLUMN()-1, Sheet1!$AL$1:$AL$50, 32-ROW())>0, 999, IF(AND(COLUMN()-1=Sheet1!$AF$4, 32-ROW()=Sheet1!$AG$4), 0, MIN(E1, F1, G1, E2, G2, E3, F3, G3) + 1))) -> 999 | G2: =IF(Sheet1!$AG$1=1, IF(AND(COLUMN()-1=Sheet1!$AF$4, 32-ROW()=Sheet1!$AG$4), 0, 999), IF(COUNTIFS(Sheet1!$AK$1:$AK$50, COLUMN()-1, Sheet1!$AL$1:$AL$50, 32-ROW())>0, 999, IF(AND(COLUMN()-1=Sheet1!$AF$4, 32-ROW()=Sheet1!$AG$4), 0, MIN(F1, G1, H1, F2, H2, F3, G3, H3) + 1))) -> 999 | H2: =IF(Sheet1!$AG$1=1, IF(AND(COLUMN()-1=Sheet1!$AF$4, 32-ROW()=Sheet1!$AG$4), 0, 999), IF(COUNTIFS(Sheet1!$AK$1:$AK$50, COLUMN()-1, Sheet1!$AL$1:$AL$50, 32-ROW())>0, 999, IF(AND(COLUMN()-1=Sheet1!$AF$4, 32-ROW()=Sheet1!$AG$4), 0, MIN(G1, H1, I1, G2, I2, G3, H3, I3) + 1))) -> 999 | I2: =IF(Sheet1!$AG$1=1, IF(AND(COLUMN()-1=Sheet1!$AF$4, 32-ROW()=Sheet1!$AG$4), 0, 999), IF(COUNTIFS(Sheet1!$AK$1:$AK$50, COLUMN()-1, Sheet1!$AL$1:$AL$50, 32-ROW())>0, 999, IF(AND(COLUMN()-1=Sheet1!$AF$4, 32-ROW()=Sheet1!$AG$4), 0, MIN(H1, I1, J1, H2, J2, H3, I3, J3) + 1))) -> 999 | ... AE2: =IF(Sheet1!$AG$1=1, IF(AND(COLUMN()-1=Sheet1!$AF$4, 32-ROW()=Sheet1!$AG$4), 0, 999), IF(COUNTIFS(Sheet1!$AK$1:$AK$50, COLUMN()-1, Sheet1!$AL$1:$AL$50, 32-ROW())>0, 999, IF(AND(COLUMN()-1=Sheet1!$AF$4, 32-ROW()=Sheet1!$AG$4), 0, MIN(AD1, AE1, AF1, AD2, AF2, AD3, AE3, AF3) + 1))) -> 0 | AF2: 999
A3: 999 | B3: =IF(Sheet1!$AG$1=1, IF(AND(COLUMN()-1=Sheet1!$AF$4, 32-ROW()=Sheet1!$AG$4), 0, 999), IF(COUNTIFS(Sheet1!$AK$1:$AK$50, COLUMN()-1, Sheet1!$AL$1:$AL$50, 32-ROW())>0, 999, IF(AND(COLUMN()-1=Sheet1!$AF$4, 32-ROW()=Sheet1!$AG$4), 0, MIN(A2, B2, C2, A3, C3, A4, B4, C4) + 1))) -> 999 | C3: =IF(Sheet1!$AG$1=1, IF(AND(COLUMN()-1=Sheet1!$AF$4, 32-ROW()=Sheet1!$AG$4), 0, 999), IF(COUNTIFS(Sheet1!$AK$1:$AK$50, COLUMN()-1, Sheet1!$AL$1:$AL$50, 32-ROW())>0, 999, IF(AND(COLUMN()-1=Sheet1!$AF$4, 32-ROW()=Sheet1!$AG$4), 0, MIN(B2, C2, D2, B3, D3, B4, C4, D4) + 1))) -> 999 | D3: =IF(Sheet1!$AG$1=1, IF(AND(COLUMN()-1=Sheet1!$AF$4, 32-ROW()=Sheet1!$AG$4), 0, 999), IF(COUNTIFS(Sheet1!$AK$1:$AK$50, COLUMN()-1, Sheet1!$AL$1:$AL$50, 32-ROW())>0, 999, IF(AND(COLUMN()-1=Sheet1!$AF$4, 32-ROW()=Sheet1!$AG$4), 0, MIN(C2, D2, E2, C3, E3, C4, D4, E4) + 1))) -> 999 | E3: =IF(Sheet1!$AG$1=1, IF(AND(COLUMN()-1=Sheet1!$AF$4, 32-ROW()=Sheet1!$AG$4), 0, 999), IF(COUNTIFS(Sheet1!$AK$1:$AK$50, COLUMN()-1, Sheet1!$AL$1:$AL$50, 32-ROW())>0, 999, IF(AND(COLUMN()-1=Sheet1!$AF$4, 32-ROW()=Sheet1!$AG$4), 0, MIN(D2, E2, F2, D3, F3, D4, E4, F4) + 1))) -> 999 | F3: =IF(Sheet1!$AG$1=1, IF(AND(COLUMN()-1=Sheet1!$AF$4, 32-ROW()=Sheet1!$AG$4), 0, 999), IF(COUNTIFS(Sheet1!$AK$1:$AK$50, COLUMN()-1, Sheet1!$AL$1:$AL$50, 32-ROW())>0, 999, IF(AND(COLUMN()-1=Sheet1!$AF$4, 32-ROW()=Sheet1!$AG$4), 0, MIN(E2, F2, G2, E3, G3, E4, F4, G4) + 1))) -> 999 | G3: =IF(Sheet1!$AG$1=1, IF(AND(COLUMN()-1=Sheet1!$AF$4, 32-ROW()=Sheet1!$AG$4), 0, 999), IF(COUNTIFS(Sheet1!$AK$1:$AK$50, COLUMN()-1, Sheet1!$AL$1:$AL$50, 32-ROW())>0, 999, IF(AND(COLUMN()-1=Sheet1!$AF$4, 32-ROW()=Sheet1!$AG$4), 0, MIN(F2, G2, H2, F3, H3, F4, G4, H4) + 1))) -> 999 | H3: =IF(Sheet1!$AG$1=1, IF(AND(COLUMN()-1=Sheet1!$AF$4, 32-ROW()=Sheet1!$AG$4), 0, 999), IF(COUNTIFS(Sheet1!$AK$1:$AK$50, COLUMN()-1, Sheet1!$AL$1:$AL$50, 32-ROW())>0, 999, IF(AND(COLUMN()-1=Sheet1!$AF$4, 32-ROW()=Sheet1!$AG$4), 0, MIN(G2, H2, I2, G3, I3, G4, H4, I4) + 1))) -> 999 | I3: =IF(Sheet1!$AG$1=1, IF(AND(COLUMN()-1=Sheet1!$AF$4, 32-ROW()=Sheet1!$AG$4), 0, 999), IF(COUNTIFS(Sheet1!$AK$1:$AK$50, COLUMN()-1, Sheet1!$AL$1:$AL$50, 32-ROW())>0, 999, IF(AND(COLUMN()-1=Sheet1!$AF$4, 32-ROW()=Sheet1!$AG$4), 0, MIN(H2, I2, J2, H3, J3, H4, I4, J4) + 1))) -> 999 | ... AE3: =IF(Sheet1!$AG$1=1, IF(AND(COLUMN()-1=Sheet1!$AF$4, 32-ROW()=Sheet1!$AG$4), 0, 999), IF(COUNTIFS(Sheet1!$AK$1:$AK$50, COLUMN()-1, Sheet1!$AL$1:$AL$50, 32-ROW())>0, 999, IF(AND(COLUMN()-1=Sheet1!$AF$4, 32-ROW()=Sheet1!$AG$4), 0, MIN(AD2, AE2, AF2, AD3, AF3, AD4, AE4, AF4) + 1))) -> 999 | AF3: 999
A4: 999 | B4: =IF(Sheet1!$AG$1=1, IF(AND(COLUMN()-1=Sheet1!$AF$4, 32-ROW()=Sheet1!$AG$4), 0, 999), IF(COUNTIFS(Sheet1!$AK$1:$AK$50, COLUMN()-1, Sheet1!$AL$1:$AL$50, 32-ROW())>0, 999, IF(AND(COLUMN()-1=Sheet1!$AF$4, 32-ROW()=Sheet1!$AG$4), 0, MIN(A3, B3, C3, A4, C4, A5, B5, C5) + 1))) -> 999 | C4: =IF(Sheet1!$AG$1=1, IF(AND(COLUMN()-1=Sheet1!$AF$4, 32-ROW()=Sheet1!$AG$4), 0, 999), IF(COUNTIFS(Sheet1!$AK$1:$AK$50, COLUMN()-1, Sheet1!$AL$1:$AL$50, 32-ROW())>0, 999, IF(AND(COLUMN()-1=Sheet1!$AF$4, 32-ROW()=Sheet1!$AG$4), 0, MIN(B3, C3, D3, B4, D4, B5, C5, D5) + 1))) -> 999 | D4: =IF(Sheet1!$AG$1=1, IF(AND(COLUMN()-1=Sheet1!$AF$4, 32-ROW()=Sheet1!$AG$4), 0, 999), IF(COUNTIFS(Sheet1!$AK$1:$AK$50, COLUMN()-1, Sheet1!$AL$1:$AL$50, 32-ROW())>0, 999, IF(AND(COLUMN()-1=Sheet1!$AF$4, 32-ROW()=Sheet1!$AG$4), 0, MIN(C3, D3, E3, C4, E4, C5, D5, E5) + 1))) -> 999 | E4: =IF(Sheet1!$AG$1=1, IF(AND(COLUMN()-1=Sheet1!$AF$4, 32-ROW()=Sheet1!$AG$4), 0, 999), IF(COUNTIFS(Sheet1!$AK$1:$AK$50, COLUMN()-1, Sheet1!$AL$1:$AL$50, 32-ROW())>0, 999, IF(AND(COLUMN()-1=Sheet1!$AF$4, 32-ROW()=Sheet1!$AG$4), 0, MIN(D3, E3, F3, D4, F4, D5, E5, F5) + 1))) -> 999 | F4: =IF(Sheet1!$AG$1=1, IF(AND(COLUMN()-1=Sheet1!$AF$4, 32-ROW()=Sheet1!$AG$4), 0, 999), IF(COUNTIFS(Sheet1!$AK$1:$AK$50, COLUMN()-1, Sheet1!$AL$1:$AL$50, 32-ROW())>0, 999, IF(AND(COLUMN()-1=Sheet1!$AF$4, 32-ROW()=Sheet1!$AG$4), 0, MIN(E3, F3, G3, E4, G4, E5, F5, G5) + 1))) -> 999 | G4: =IF(Sheet1!$AG$1=1, IF(AND(COLUMN()-1=Sheet1!$AF$4, 32-ROW()=Sheet1!$AG$4), 0, 999), IF(COUNTIFS(Sheet1!$AK$1:$AK$50, COLUMN()-1, Sheet1!$AL$1:$AL$50, 32-ROW())>0, 999, IF(AND(COLUMN()-1=Sheet1!$AF$4, 32-ROW()=Sheet1!$AG$4), 0, MIN(F3, G3, H3, F4, H4, F5, G5, H5) + 1))) -> 999 | H4: =IF(Sheet1!$AG$1=1, IF(AND(COLUMN()-1=Sheet1!$AF$4, 32-ROW()=Sheet1!$AG$4), 0, 999), IF(COUNTIFS(Sheet1!$AK$1:$AK$50, COLUMN()-1, Sheet1!$AL$1:$AL$50, 32-ROW())>0, 999, IF(AND(COLUMN()-1=Sheet1!$AF$4, 32-ROW()=Sheet1!$AG$4), 0, MIN(G3, H3, I3, G4, I4, G5, H5, I5) + 1))) -> 999 | I4: =IF(Sheet1!$AG$1=1, IF(AND(COLUMN()-1=Sheet1!$AF$4, 32-ROW()=Sheet1!$AG$4), 0, 999), IF(COUNTIFS(Sheet1!$AK$1:$AK$50, COLUMN()-1, Sheet1!$AL$1:$AL$50, 32-ROW())>0, 999, IF(AND(COLUMN()-1=Sheet1!$AF$4, 32-ROW()=Sheet1!$AG$4), 0, MIN(H3, I3, J3, H4, J4, H5, I5, J5) + 1))) -> 999 | ... AE4: =IF(Sheet1!$AG$1=1, IF(AND(COLUMN()-1=Sheet1!$AF$4, 32-ROW()=Sheet1!$AG$4), 0, 999), IF(COUNTIFS(Sheet1!$AK$1:$AK$50, COLUMN()-1, Sheet1!$AL$1:$AL$50, 32-ROW())>0, 999, IF(AND(COLUMN()-1=Sheet1!$AF$4, 32-ROW()=Sheet1!$AG$4), 0, MIN(AD3, AE3, AF3, AD4, AF4, AD5, AE5, AF5) + 1))) -> 999 | AF4: 999
A5: 999 | B5: =IF(Sheet1!$AG$1=1, IF(AND(COLUMN()-1=Sheet1!$AF$4, 32-ROW()=Sheet1!$AG$4), 0, 999), IF(COUNTIFS(Sheet1!$AK$1:$AK$50, COLUMN()-1, Sheet1!$AL$1:$AL$50, 32-ROW())>0, 999, IF(AND(COLUMN()-1=Sheet1!$AF$4, 32-ROW()=Sheet1!$AG$4), 0, MIN(A4, B4, C4, A5, C5, A6, B6, C6) + 1))) -> 999 | C5: =IF(Sheet1!$AG$1=1, IF(AND(COLUMN()-1=Sheet1!$AF$4, 32-ROW()=Sheet1!$AG$4), 0, 999), IF(COUNTIFS(Sheet1!$AK$1:$AK$50, COLUMN()-1, Sheet1!$AL$1:$AL$50, 32-ROW())>0, 999, IF(AND(COLUMN()-1=Sheet1!$AF$4, 32-ROW()=Sheet1!$AG$4), 0, MIN(B4, C4, D4, B5, D5, B6, C6, D6) + 1))) -> 999 | D5: =IF(Sheet1!$AG$1=1, IF(AND(COLUMN()-1=Sheet1!$AF$4, 32-ROW()=Sheet1!$AG$4), 0, 999), IF(COUNTIFS(Sheet1!$AK$1:$AK$50, COLUMN()-1, Sheet1!$AL$1:$AL$50, 32-ROW())>0, 999, IF(AND(COLUMN()-1=Sheet1!$AF$4, 32-ROW()=Sheet1!$AG$4), 0, MIN(C4, D4, E4, C5, E5, C6, D6, E6) + 1))) -> 999 | E5: =IF(Sheet1!$AG$1=1, IF(AND(COLUMN()-1=Sheet1!$AF$4, 32-ROW()=Sheet1!$AG$4), 0, 999), IF(COUNTIFS(Sheet1!$AK$1:$AK$50, COLUMN()-1, Sheet1!$AL$1:$AL$50, 32-ROW())>0, 999, IF(AND(COLUMN()-1=Sheet1!$AF$4, 32-ROW()=Sheet1!$AG$4), 0, MIN(D4, E4, F4, D5, F5, D6, E6, F6) + 1))) -> 999 | F5: =IF(Sheet1!$AG$1=1, IF(AND(COLUMN()-1=Sheet1!$AF$4, 32-ROW()=Sheet1!$AG$4), 0, 999), IF(COUNTIFS(Sheet1!$AK$1:$AK$50, COLUMN()-1, Sheet1!$AL$1:$AL$50, 32-ROW())>0, 999, IF(AND(COLUMN()-1=Sheet1!$AF$4, 32-ROW()=Sheet1!$AG$4), 0, MIN(E4, F4, G4, E5, G5, E6, F6, G6) + 1))) -> 999 | G5: =IF(Sheet1!$AG$1=1, IF(AND(COLUMN()-1=Sheet1!$AF$4, 32-ROW()=Sheet1!$AG$4), 0, 999), IF(COUNTIFS(Sheet1!$AK$1:$AK$50, COLUMN()-1, Sheet1!$AL$1:$AL$50, 32-ROW())>0, 999, IF(AND(COLUMN()-1=Sheet1!$AF$4, 32-ROW()=Sheet1!$AG$4), 0, MIN(F4, G4, H4, F5, H5, F6, G6, H6) + 1))) -> 999 | H5: =IF(Sheet1!$AG$1=1, IF(AND(COLUMN()-1=Sheet1!$AF$4, 32-ROW()=Sheet1!$AG$4), 0, 999), IF(COUNTIFS(Sheet1!$AK$1:$AK$50, COLUMN()-1, Sheet1!$AL$1:$AL$50, 32-ROW())>0, 999, IF(AND(COLUMN()-1=Sheet1!$AF$4, 32-ROW()=Sheet1!$AG$4), 0, MIN(G4, H4, I4, G5, I5, G6, H6, I6) + 1))) -> 999 | I5: =IF(Sheet1!$AG$1=1, IF(AND(COLUMN()-1=Sheet1!$AF$4, 32-ROW()=Sheet1!$AG$4), 0, 999), IF(COUNTIFS(Sheet1!$AK$1:$AK$50, COLUMN()-1, Sheet1!$AL$1:$AL$50, 32-ROW())>0, 999, IF(AND(COLUMN()-1=Sheet1!$AF$4, 32-ROW()=Sheet1!$AG$4), 0, MIN(H4, I4, J4, H5, J5, H6, I6, J6) + 1))) -> 999 | ... AE5: =IF(Sheet1!$AG$1=1, IF(AND(COLUMN()-1=Sheet1!$AF$4, 32-ROW()=Sheet1!$AG$4), 0, 999), IF(COUNTIFS(Sheet1!$AK$1:$AK$50, COLUMN()-1, Sheet1!$AL$1:$AL$50, 32-ROW())>0, 999, IF(AND(COLUMN()-1=Sheet1!$AF$4, 32-ROW()=Sheet1!$AG$4), 0, MIN(AD4, AE4, AF4, AD5, AF5, AD6, AE6, AF6) + 1))) -> 999 | AF5: 999
A6: 999 | B6: =IF(Sheet1!$AG$1=1, IF(AND(COLUMN()-1=Sheet1!$AF$4, 32-ROW()=Sheet1!$AG$4), 0, 999), IF(COUNTIFS(Sheet1!$AK$1:$AK$50, COLUMN()-1, Sheet1!$AL$1:$AL$50, 32-ROW())>0, 999, IF(AND(COLUMN()-1=Sheet1!$AF$4, 32-ROW()=Sheet1!$AG$4), 0, MIN(A5, B5, C5, A6, C6, A7, B7, C7) + 1))) -> 999 | C6: =IF(Sheet1!$AG$1=1, IF(AND(COLUMN()-1=Sheet1!$AF$4, 32-ROW()=Sheet1!$AG$4), 0, 999), IF(COUNTIFS(Sheet1!$AK$1:$AK$50, COLUMN()-1, Sheet1!$AL$1:$AL$50, 32-ROW())>0, 999, IF(AND(COLUMN()-1=Sheet1!$AF$4, 32-ROW()=Sheet1!$AG$4), 0, MIN(B5, C5, D5, B6, D6, B7, C7, D7) + 1))) -> 999 | D6: =IF(Sheet1!$AG$1=1, IF(AND(COLUMN()-1=Sheet1!$AF$4, 32-ROW()=Sheet1!$AG$4), 0, 999), IF(COUNTIFS(Sheet1!$AK$1:$AK$50, COLUMN()-1, Sheet1!$AL$1:$AL$50, 32-ROW())>0, 999, IF(AND(COLUMN()-1=Sheet1!$AF$4, 32-ROW()=Sheet1!$AG$4), 0, MIN(C5, D5, E5, C6, E6, C7, D7, E7) + 1))) -> 999 | E6: =IF(Sheet1!$AG$1=1, IF(AND(COLUMN()-1=Sheet1!$AF$4, 32-ROW()=Sheet1!$AG$4), 0, 999), IF(COUNTIFS(Sheet1!$AK$1:$AK$50, COLUMN()-1, Sheet1!$AL$1:$AL$50, 32-ROW())>0, 999, IF(AND(COLUMN()-1=Sheet1!$AF$4, 32-ROW()=Sheet1!$AG$4), 0, MIN(D5, E5, F5, D6, F6, D7, E7, F7) + 1))) -> 999 | F6: =IF(Sheet1!$AG$1=1, IF(AND(COLUMN()-1=Sheet1!$AF$4, 32-ROW()=Sheet1!$AG$4), 0, 999), IF(COUNTIFS(Sheet1!$AK$1:$AK$50, COLUMN()-1, Sheet1!$AL$1:$AL$50, 32-ROW())>0, 999, IF(AND(COLUMN()-1=Sheet1!$AF$4, 32-ROW()=Sheet1!$AG$4), 0, MIN(E5, F5, G5, E6, G6, E7, F7, G7) + 1))) -> 999 | G6: =IF(Sheet1!$AG$1=1, IF(AND(COLUMN()-1=Sheet1!$AF$4, 32-ROW()=Sheet1!$AG$4), 0, 999), IF(COUNTIFS(Sheet1!$AK$1:$AK$50, COLUMN()-1, Sheet1!$AL$1:$AL$50, 32-ROW())>0, 999, IF(AND(COLUMN()-1=Sheet1!$AF$4, 32-ROW()=Sheet1!$AG$4), 0, MIN(F5, G5, H5, F6, H6, F7, G7, H7) + 1))) -> 999 | H6: =IF(Sheet1!$AG$1=1, IF(AND(COLUMN()-1=Sheet1!$AF$4, 32-ROW()=Sheet1!$AG$4), 0, 999), IF(COUNTIFS(Sheet1!$AK$1:$AK$50, COLUMN()-1, Sheet1!$AL$1:$AL$50, 32-ROW())>0, 999, IF(AND(COLUMN()-1=Sheet1!$AF$4, 32-ROW()=Sheet1!$AG$4), 0, MIN(G5, H5, I5, G6, I6, G7, H7, I7) + 1))) -> 999 | I6: =IF(Sheet1!$AG$1=1, IF(AND(COLUMN()-1=Sheet1!$AF$4, 32-ROW()=Sheet1!$AG$4), 0, 999), IF(COUNTIFS(Sheet1!$AK$1:$AK$50, COLUMN()-1, Sheet1!$AL$1:$AL$50, 32-ROW())>0, 999, IF(AND(COLUMN()-1=Sheet1!$AF$4, 32-ROW()=Sheet1!$AG$4), 0, MIN(H5, I5, J5, H6, J6, H7, I7, J7) + 1))) -> 999 | ... AE6: =IF(Sheet1!$AG$1=1, IF(AND(COLUMN()-1=Sheet1!$AF$4, 32-ROW()=Sheet1!$AG$4), 0, 999), IF(COUNTIFS(Sheet1!$AK$1:$AK$50, COLUMN()-1, Sheet1!$AL$1:$AL$50, 32-ROW())>0, 999, IF(AND(COLUMN()-1=Sheet1!$AF$4, 32-ROW()=Sheet1!$AG$4), 0, MIN(AD5, AE5, AF5, AD6, AF6, AD7, AE7, AF7) + 1))) -> 999 | AF6: 999
A7: 999 | B7: =IF(Sheet1!$AG$1=1, IF(AND(COLUMN()-1=Sheet1!$AF$4, 32-ROW()=Sheet1!$AG$4), 0, 999), IF(COUNTIFS(Sheet1!$AK$1:$AK$50, COLUMN()-1, Sheet1!$AL$1:$AL$50, 32-ROW())>0, 999, IF(AND(COLUMN()-1=Sheet1!$AF$4, 32-ROW()=Sheet1!$AG$4), 0, MIN(A6, B6, C6, A7, C7, A8, B8, C8) + 1))) -> 999 | C7: =IF(Sheet1!$AG$1=1, IF(AND(COLUMN()-1=Sheet1!$AF$4, 32-ROW()=Sheet1!$AG$4), 0, 999), IF(COUNTIFS(Sheet1!$AK$1:$AK$50, COLUMN()-1, Sheet1!$AL$1:$AL$50, 32-ROW())>0, 999, IF(AND(COLUMN()-1=Sheet1!$AF$4, 32-ROW()=Sheet1!$AG$4), 0, MIN(B6, C6, D6, B7, D7, B8, C8, D8) + 1))) -> 999 | D7: =IF(Sheet1!$AG$1=1, IF(AND(COLUMN()-1=Sheet1!$AF$4, 32-ROW()=Sheet1!$AG$4), 0, 999), IF(COUNTIFS(Sheet1!$AK$1:$AK$50, COLUMN()-1, Sheet1!$AL$1:$AL$50, 32-ROW())>0, 999, IF(AND(COLUMN()-1=Sheet1!$AF$4, 32-ROW()=Sheet1!$AG$4), 0, MIN(C6, D6, E6, C7, E7, C8, D8, E8) + 1))) -> 999 | E7: =IF(Sheet1!$AG$1=1, IF(AND(COLUMN()-1=Sheet1!$AF$4, 32-ROW()=Sheet1!$AG$4), 0, 999), IF(COUNTIFS(Sheet1!$AK$1:$AK$50, COLUMN()-1, Sheet1!$AL$1:$AL$50, 32-ROW())>0, 999, IF(AND(COLUMN()-1=Sheet1!$AF$4, 32-ROW()=Sheet1!$AG$4), 0, MIN(D6, E6, F6, D7, F7, D8, E8, F8) + 1))) -> 999 | F7: =IF(Sheet1!$AG$1=1, IF(AND(COLUMN()-1=Sheet1!$AF$4, 32-ROW()=Sheet1!$AG$4), 0, 999), IF(COUNTIFS(Sheet1!$AK$1:$AK$50, COLUMN()-1, Sheet1!$AL$1:$AL$50, 32-ROW())>0, 999, IF(AND(COLUMN()-1=Sheet1!$AF$4, 32-ROW()=Sheet1!$AG$4), 0, MIN(E6, F6, G6, E7, G7, E8, F8, G8) + 1))) -> 999 | G7: =IF(Sheet1!$AG$1=1, IF(AND(COLUMN()-1=Sheet1!$AF$4, 32-ROW()=Sheet1!$AG$4), 0, 999), IF(COUNTIFS(Sheet1!$AK$1:$AK$50, COLUMN()-1, Sheet1!$AL$1:$AL$50, 32-ROW())>0, 999, IF(AND(COLUMN()-1=Sheet1!$AF$4, 32-ROW()=Sheet1!$AG$4), 0, MIN(F6, G6, H6, F7, H7, F8, G8, H8) + 1))) -> 999 | H7: =IF(Sheet1!$AG$1=1, IF(AND(COLUMN()-1=Sheet1!$AF$4, 32-ROW()=Sheet1!$AG$4), 0, 999), IF(COUNTIFS(Sheet1!$AK$1:$AK$50, COLUMN()-1, Sheet1!$AL$1:$AL$50, 32-ROW())>0, 999, IF(AND(COLUMN()-1=Sheet1!$AF$4, 32-ROW()=Sheet1!$AG$4), 0, MIN(G6, H6, I6, G7, I7, G8, H8, I8) + 1))) -> 999 | I7: =IF(Sheet1!$AG$1=1, IF(AND(COLUMN()-1=Sheet1!$AF$4, 32-ROW()=Sheet1!$AG$4), 0, 999), IF(COUNTIFS(Sheet1!$AK$1:$AK$50, COLUMN()-1, Sheet1!$AL$1:$AL$50, 32-ROW())>0, 999, IF(AND(COLUMN()-1=Sheet1!$AF$4, 32-ROW()=Sheet1!$AG$4), 0, MIN(H6, I6, J6, H7, J7, H8, I8, J8) + 1))) -> 999 | ... AE7: =IF(Sheet1!$AG$1=1, IF(AND(COLUMN()-1=Sheet1!$AF$4, 32-ROW()=Sheet1!$AG$4), 0, 999), IF(COUNTIFS(Sheet1!$AK$1:$AK$50, COLUMN()-1, Sheet1!$AL$1:$AL$50, 32-ROW())>0, 999, IF(AND(COLUMN()-1=Sheet1!$AF$4, 32-ROW()=Sheet1!$AG$4), 0, MIN(AD6, AE6, AF6, AD7, AF7, AD8, AE8, AF8) + 1))) -> 999 | AF7: 999
A8: 999 | B8: =IF(Sheet1!$AG$1=1, IF(AND(COLUMN()-1=Sheet1!$AF$4, 32-ROW()=Sheet1!$AG$4), 0, 999), IF(COUNTIFS(Sheet1!$AK$1:$AK$50, COLUMN()-1, Sheet1!$AL$1:$AL$50, 32-ROW())>0, 999, IF(AND(COLUMN()-1=Sheet1!$AF$4, 32-ROW()=Sheet1!$AG$4), 0, MIN(A7, B7, C7, A8, C8, A9, B9, C9) + 1))) -> 999 | C8: =IF(Sheet1!$AG$1=1, IF(AND(COLUMN()-1=Sheet1!$AF$4, 32-ROW()=Sheet1!$AG$4), 0, 999), IF(COUNTIFS(Sheet1!$AK$1:$AK$50, COLUMN()-1, Sheet1!$AL$1:$AL$50, 32-ROW())>0, 999, IF(AND(COLUMN()-1=Sheet1!$AF$4, 32-ROW()=Sheet1!$AG$4), 0, MIN(B7, C7, D7, B8, D8, B9, C9, D9) + 1))) -> 999 | D8: =IF(Sheet1!$AG$1=1, IF(AND(COLUMN()-1=Sheet1!$AF$4, 32-ROW()=Sheet1!$AG$4), 0, 999), IF(COUNTIFS(Sheet1!$AK$1:$AK$50, COLUMN()-1, Sheet1!$AL$1:$AL$50, 32-ROW())>0, 999, IF(AND(COLUMN()-1=Sheet1!$AF$4, 32-ROW()=Sheet1!$AG$4), 0, MIN(C7, D7, E7, C8, E8, C9, D9, E9) + 1))) -> 999 | E8: =IF(Sheet1!$AG$1=1, IF(AND(COLUMN()-1=Sheet1!$AF$4, 32-ROW()=Sheet1!$AG$4), 0, 999), IF(COUNTIFS(Sheet1!$AK$1:$AK$50, COLUMN()-1, Sheet1!$AL$1:$AL$50, 32-ROW())>0, 999, IF(AND(COLUMN()-1=Sheet1!$AF$4, 32-ROW()=Sheet1!$AG$4), 0, MIN(D7, E7, F7, D8, F8, D9, E9, F9) + 1))) -> 999 | F8: =IF(Sheet1!$AG$1=1, IF(AND(COLUMN()-1=Sheet1!$AF$4, 32-ROW()=Sheet1!$AG$4), 0, 999), IF(COUNTIFS(Sheet1!$AK$1:$AK$50, COLUMN()-1, Sheet1!$AL$1:$AL$50, 32-ROW())>0, 999, IF(AND(COLUMN()-1=Sheet1!$AF$4, 32-ROW()=Sheet1!$AG$4), 0, MIN(E7, F7, G7, E8, G8, E9, F9, G9) + 1))) -> 999 | G8: =IF(Sheet1!$AG$1=1, IF(AND(COLUMN()-1=Sheet1!$AF$4, 32-ROW()=Sheet1!$AG$4), 0, 999), IF(COUNTIFS(Sheet1!$AK$1:$AK$50, COLUMN()-1, Sheet1!$AL$1:$AL$50, 32-ROW())>0, 999, IF(AND(COLUMN()-1=Sheet1!$AF$4, 32-ROW()=Sheet1!$AG$4), 0, MIN(F7, G7, H7, F8, H8, F9, G9, H9) + 1))) -> 999 | H8: =IF(Sheet1!$AG$1=1, IF(AND(COLUMN()-1=Sheet1!$AF$4, 32-ROW()=Sheet1!$AG$4), 0, 999), IF(COUNTIFS(Sheet1!$AK$1:$AK$50, COLUMN()-1, Sheet1!$AL$1:$AL$50, 32-ROW())>0, 999, IF(AND(COLUMN()-1=Sheet1!$AF$4, 32-ROW()=Sheet1!$AG$4), 0, MIN(G7, H7, I7, G8, I8, G9, H9, I9) + 1))) -> 999 | I8: =IF(Sheet1!$AG$1=1, IF(AND(COLUMN()-1=Sheet1!$AF$4, 32-ROW()=Sheet1!$AG$4), 0, 999), IF(COUNTIFS(Sheet1!$AK$1:$AK$50, COLUMN()-1, Sheet1!$AL$1:$AL$50, 32-ROW())>0, 999, IF(AND(COLUMN()-1=Sheet1!$AF$4, 32-ROW()=Sheet1!$AG$4), 0, MIN(H7, I7, J7, H8, J8, H9, I9, J9) + 1))) -> 999 | ... AE8: =IF(Sheet1!$AG$1=1, IF(AND(COLUMN()-1=Sheet1!$AF$4, 32-ROW()=Sheet1!$AG$4), 0, 999), IF(COUNTIFS(Sheet1!$AK$1:$AK$50, COLUMN()-1, Sheet1!$AL$1:$AL$50, 32-ROW())>0, 999, IF(AND(COLUMN()-1=Sheet1!$AF$4, 32-ROW()=Sheet1!$AG$4), 0, MIN(AD7, AE7, AF7, AD8, AF8, AD9, AE9, AF9) + 1))) -> 999 | AF8: 999
A9: 999 | B9: =IF(Sheet1!$AG$1=1, IF(AND(COLUMN()-1=Sheet1!$AF$4, 32-ROW()=Sheet1!$AG$4), 0, 999), IF(COUNTIFS(Sheet1!$AK$1:$AK$50, COLUMN()-1, Sheet1!$AL$1:$AL$50, 32-ROW())>0, 999, IF(AND(COLUMN()-1=Sheet1!$AF$4, 32-ROW()=Sheet1!$AG$4), 0, MIN(A8, B8, C8, A9, C9, A10, B10, C10) + 1))) -> 999 | C9: =IF(Sheet1!$AG$1=1, IF(AND(COLUMN()-1=Sheet1!$AF$4, 32-ROW()=Sheet1!$AG$4), 0, 999), IF(COUNTIFS(Sheet1!$AK$1:$AK$50, COLUMN()-1, Sheet1!$AL$1:$AL$50, 32-ROW())>0, 999, IF(AND(COLUMN()-1=Sheet1!$AF$4, 32-ROW()=Sheet1!$AG$4), 0, MIN(B8, C8, D8, B9, D9, B10, C10, D10) + 1))) -> 999 | D9: =IF(Sheet1!$AG$1=1, IF(AND(COLUMN()-1=Sheet1!$AF$4, 32-ROW()=Sheet1!$AG$4), 0, 999), IF(COUNTIFS(Sheet1!$AK$1:$AK$50, COLUMN()-1, Sheet1!$AL$1:$AL$50, 32-ROW())>0, 999, IF(AND(COLUMN()-1=Sheet1!$AF$4, 32-ROW()=Sheet1!$AG$4), 0, MIN(C8, D8, E8, C9, E9, C10, D10, E10) + 1))) -> 999 | E9: =IF(Sheet1!$AG$1=1, IF(AND(COLUMN()-1=Sheet1!$AF$4, 32-ROW()=Sheet1!$AG$4), 0, 999), IF(COUNTIFS(Sheet1!$AK$1:$AK$50, COLUMN()-1, Sheet1!$AL$1:$AL$50, 32-ROW())>0, 999, IF(AND(COLUMN()-1=Sheet1!$AF$4, 32-ROW()=Sheet1!$AG$4), 0, MIN(D8, E8, F8, D9, F9, D10, E10, F10) + 1))) -> 999 | F9: =IF(Sheet1!$AG$1=1, IF(AND(COLUMN()-1=Sheet1!$AF$4, 32-ROW()=Sheet1!$AG$4), 0, 999), IF(COUNTIFS(Sheet1!$AK$1:$AK$50, COLUMN()-1, Sheet1!$AL$1:$AL$50, 32-ROW())>0, 999, IF(AND(COLUMN()-1=Sheet1!$AF$4, 32-ROW()=Sheet1!$AG$4), 0, MIN(E8, F8, G8, E9, G9, E10, F10, G10) + 1))) -> 999 | G9: =IF(Sheet1!$AG$1=1, IF(AND(COLUMN()-1=Sheet1!$AF$4, 32-ROW()=Sheet1!$AG$4), 0, 999), IF(COUNTIFS(Sheet1!$AK$1:$AK$50, COLUMN()-1, Sheet1!$AL$1:$AL$50, 32-ROW())>0, 999, IF(AND(COLUMN()-1=Sheet1!$AF$4, 32-ROW()=Sheet1!$AG$4), 0, MIN(F8, G8, H8, F9, H9, F10, G10, H10) + 1))) -> 999 | H9: =IF(Sheet1!$AG$1=1, IF(AND(COLUMN()-1=Sheet1!$AF$4, 32-ROW()=Sheet1!$AG$4), 0, 999), IF(COUNTIFS(Sheet1!$AK$1:$AK$50, COLUMN()-1, Sheet1!$AL$1:$AL$50, 32-ROW())>0, 999, IF(AND(COLUMN()-1=Sheet1!$AF$4, 32-ROW()=Sheet1!$AG$4), 0, MIN(G8, H8, I8, G9, I9, G10, H10, I10) + 1))) -> 999 | I9: =IF(Sheet1!$AG$1=1, IF(AND(COLUMN()-1=Sheet1!$AF$4, 32-ROW()=Sheet1!$AG$4), 0, 999), IF(COUNTIFS(Sheet1!$AK$1:$AK$50, COLUMN()-1, Sheet1!$AL$1:$AL$50, 32-ROW())>0, 999, IF(AND(COLUMN()-1=Sheet1!$AF$4, 32-ROW()=Sheet1!$AG$4), 0, MIN(H8, I8, J8, H9, J9, H10, I10, J10) + 1))) -> 999 | ... AE9: =IF(Sheet1!$AG$1=1, IF(AND(COLUMN()-1=Sheet1!$AF$4, 32-ROW()=Sheet1!$AG$4), 0, 999), IF(COUNTIFS(Sheet1!$AK$1:$AK$50, COLUMN()-1, Sheet1!$AL$1:$AL$50, 32-ROW())>0, 999, IF(AND(COLUMN()-1=Sheet1!$AF$4, 32-ROW()=Sheet1!$AG$4), 0, MIN(AD8, AE8, AF8, AD9, AF9, AD10, AE10, AF10) + 1))) -> 999 | AF9: 999
A10: 999 | B10: =IF(Sheet1!$AG$1=1, IF(AND(COLUMN()-1=Sheet1!$AF$4, 32-ROW()=Sheet1!$AG$4), 0, 999), IF(COUNTIFS(Sheet1!$AK$1:$AK$50, COLUMN()-1, Sheet1!$AL$1:$AL$50, 32-ROW())>0, 999, IF(AND(COLUMN()-1=Sheet1!$AF$4, 32-ROW()=Sheet1!$AG$4), 0, MIN(A9, B9, C9, A10, C10, A11, B11, C11) + 1))) -> 999 | C10: =IF(Sheet1!$AG$1=1, IF(AND(COLUMN()-1=Sheet1!$AF$4, 32-ROW()=Sheet1!$AG$4), 0, 999), IF(COUNTIFS(Sheet1!$AK$1:$AK$50, COLUMN()-1, Sheet1!$AL$1:$AL$50, 32-ROW())>0, 999, IF(AND(COLUMN()-1=Sheet1!$AF$4, 32-ROW()=Sheet1!$AG$4), 0, MIN(B9, C9, D9, B10, D10, B11, C11, D11) + 1))) -> 999 | D10: =IF(Sheet1!$AG$1=1, IF(AND(COLUMN()-1=Sheet1!$AF$4, 32-ROW()=Sheet1!$AG$4), 0, 999), IF(COUNTIFS(Sheet1!$AK$1:$AK$50, COLUMN()-1, Sheet1!$AL$1:$AL$50, 32-ROW())>0, 999, IF(AND(COLUMN()-1=Sheet1!$AF$4, 32-ROW()=Sheet1!$AG$4), 0, MIN(C9, D9, E9, C10, E10, C11, D11, E11) + 1))) -> 999 | E10: =IF(Sheet1!$AG$1=1, IF(AND(COLUMN()-1=Sheet1!$AF$4, 32-ROW()=Sheet1!$AG$4), 0, 999), IF(COUNTIFS(Sheet1!$AK$1:$AK$50, COLUMN()-1, Sheet1!$AL$1:$AL$50, 32-ROW())>0, 999, IF(AND(COLUMN()-1=Sheet1!$AF$4, 32-ROW()=Sheet1!$AG$4), 0, MIN(D9, E9, F9, D10, F10, D11, E11, F11) + 1))) -> 999 | F10: =IF(Sheet1!$AG$1=1, IF(AND(COLUMN()-1=Sheet1!$AF$4, 32-ROW()=Sheet1!$AG$4), 0, 999), IF(COUNTIFS(Sheet1!$AK$1:$AK$50, COLUMN()-1, Sheet1!$AL$1:$AL$50, 32-ROW())>0, 999, IF(AND(COLUMN()-1=Sheet1!$AF$4, 32-ROW()=Sheet1!$AG$4), 0, MIN(E9, F9, G9, E10, G10, E11, F11, G11) + 1))) -> 999 | G10: =IF(Sheet1!$AG$1=1, IF(AND(COLUMN()-1=Sheet1!$AF$4, 32-ROW()=Sheet1!$AG$4), 0, 999), IF(COUNTIFS(Sheet1!$AK$1:$AK$50, COLUMN()-1, Sheet1!$AL$1:$AL$50, 32-ROW())>0, 999, IF(AND(COLUMN()-1=Sheet1!$AF$4, 32-ROW()=Sheet1!$AG$4), 0, MIN(F9, G9, H9, F10, H10, F11, G11, H11) + 1))) -> 999 | H10: =IF(Sheet1!$AG$1=1, IF(AND(COLUMN()-1=Sheet1!$AF$4, 32-ROW()=Sheet1!$AG$4), 0, 999), IF(COUNTIFS(Sheet1!$AK$1:$AK$50, COLUMN()-1, Sheet1!$AL$1:$AL$50, 32-ROW())>0, 999, IF(AND(COLUMN()-1=Sheet1!$AF$4, 32-ROW()=Sheet1!$AG$4), 0, MIN(G9, H9, I9, G10, I10, G11, H11, I11) + 1))) -> 999 | I10: =IF(Sheet1!$AG$1=1, IF(AND(COLUMN()-1=Sheet1!$AF$4, 32-ROW()=Sheet1!$AG$4), 0, 999), IF(COUNTIFS(Sheet1!$AK$1:$AK$50, COLUMN()-1, Sheet1!$AL$1:$AL$50, 32-ROW())>0, 999, IF(AND(COLUMN()-1=Sheet1!$AF$4, 32-ROW()=Sheet1!$AG$4), 0, MIN(H9, I9, J9, H10, J10, H11, I11, J11) + 1))) -> 999 | ... AE10: =IF(Sheet1!$AG$1=1, IF(AND(COLUMN()-1=Sheet1!$AF$4, 32-ROW()=Sheet1!$AG$4), 0, 999), IF(COUNTIFS(Sheet1!$AK$1:$AK$50, COLUMN()-1, Sheet1!$AL$1:$AL$50, 32-ROW())>0, 999, IF(AND(COLUMN()-1=Sheet1!$AF$4, 32-ROW()=Sheet1!$AG$4), 0, MIN(AD9, AE9, AF9, AD10, AF10, AD11, AE11, AF11) + 1))) -> 999 | AF10: 999
A11: 999 | B11: =IF(Sheet1!$AG$1=1, IF(AND(COLUMN()-1=Sheet1!$AF$4, 32-ROW()=Sheet1!$AG$4), 0, 999), IF(COUNTIFS(Sheet1!$AK$1:$AK$50, COLUMN()-1, Sheet1!$AL$1:$AL$50, 32-ROW())>0, 999, IF(AND(COLUMN()-1=Sheet1!$AF$4, 32-ROW()=Sheet1!$AG$4), 0, MIN(A10, B10, C10, A11, C11, A12, B12, C12) + 1))) -> 999 | C11: =IF(Sheet1!$AG$1=1, IF(AND(COLUMN()-1=Sheet1!$AF$4, 32-ROW()=Sheet1!$AG$4), 0, 999), IF(COUNTIFS(Sheet1!$AK$1:$AK$50, COLUMN()-1, Sheet1!$AL$1:$AL$50, 32-ROW())>0, 999, IF(AND(COLUMN()-1=Sheet1!$AF$4, 32-ROW()=Sheet1!$AG$4), 0, MIN(B10, C10, D10, B11, D11, B12, C12, D12) + 1))) -> 999 | D11: =IF(Sheet1!$AG$1=1, IF(AND(COLUMN()-1=Sheet1!$AF$4, 32-ROW()=Sheet1!$AG$4), 0, 999), IF(COUNTIFS(Sheet1!$AK$1:$AK$50, COLUMN()-1, Sheet1!$AL$1:$AL$50, 32-ROW())>0, 999, IF(AND(COLUMN()-1=Sheet1!$AF$4, 32-ROW()=Sheet1!$AG$4), 0, MIN(C10, D10, E10, C11, E11, C12, D12, E12) + 1))) -> 999 | E11: =IF(Sheet1!$AG$1=1, IF(AND(COLUMN()-1=Sheet1!$AF$4, 32-ROW()=Sheet1!$AG$4), 0, 999), IF(COUNTIFS(Sheet1!$AK$1:$AK$50, COLUMN()-1, Sheet1!$AL$1:$AL$50, 32-ROW())>0, 999, IF(AND(COLUMN()-1=Sheet1!$AF$4, 32-ROW()=Sheet1!$AG$4), 0, MIN(D10, E10, F10, D11, F11, D12, E12, F12) + 1))) -> 999 | F11: =IF(Sheet1!$AG$1=1, IF(AND(COLUMN()-1=Sheet1!$AF$4, 32-ROW()=Sheet1!$AG$4), 0, 999), IF(COUNTIFS(Sheet1!$AK$1:$AK$50, COLUMN()-1, Sheet1!$AL$1:$AL$50, 32-ROW())>0, 999, IF(AND(COLUMN()-1=Sheet1!$AF$4, 32-ROW()=Sheet1!$AG$4), 0, MIN(E10, F10, G10, E11, G11, E12, F12, G12) + 1))) -> 999 | G11: =IF(Sheet1!$AG$1=1, IF(AND(COLUMN()-1=Sheet1!$AF$4, 32-ROW()=Sheet1!$AG$4), 0, 999), IF(COUNTIFS(Sheet1!$AK$1:$AK$50, COLUMN()-1, Sheet1!$AL$1:$AL$50, 32-ROW())>0, 999, IF(AND(COLUMN()-1=Sheet1!$AF$4, 32-ROW()=Sheet1!$AG$4), 0, MIN(F10, G10, H10, F11, H11, F12, G12, H12) + 1))) -> 999 | H11: =IF(Sheet1!$AG$1=1, IF(AND(COLUMN()-1=Sheet1!$AF$4, 32-ROW()=Sheet1!$AG$4), 0, 999), IF(COUNTIFS(Sheet1!$AK$1:$AK$50, COLUMN()-1, Sheet1!$AL$1:$AL$50, 32-ROW())>0, 999, IF(AND(COLUMN()-1=Sheet1!$AF$4, 32-ROW()=Sheet1!$AG$4), 0, MIN(G10, H10, I10, G11, I11, G12, H12, I12) + 1))) -> 999 | I11: =IF(Sheet1!$AG$1=1, IF(AND(COLUMN()-1=Sheet1!$AF$4, 32-ROW()=Sheet1!$AG$4), 0, 999), IF(COUNTIFS(Sheet1!$AK$1:$AK$50, COLUMN()-1, Sheet1!$AL$1:$AL$50, 32-ROW())>0, 999, IF(AND(COLUMN()-1=Sheet1!$AF$4, 32-ROW()=Sheet1!$AG$4), 0, MIN(H10, I10, J10, H11, J11, H12, I12, J12) + 1))) -> 999 | ... AE11: =IF(Sheet1!$AG$1=1, IF(AND(COLUMN()-1=Sheet1!$AF$4, 32-ROW()=Sheet1!$AG$4), 0, 999), IF(COUNTIFS(Sheet1!$AK$1:$AK$50, COLUMN()-1, Sheet1!$AL$1:$AL$50, 32-ROW())>0, 999, IF(AND(COLUMN()-1=Sheet1!$AF$4, 32-ROW()=Sheet1!$AG$4), 0, MIN(AD10, AE10, AF10, AD11, AF11, AD12, AE12, AF12) + 1))) -> 999 | AF11: 999
A12: 999 | B12: =IF(Sheet1!$AG$1=1, IF(AND(COLUMN()-1=Sheet1!$AF$4, 32-ROW()=Sheet1!$AG$4), 0, 999), IF(COUNTIFS(Sheet1!$AK$1:$AK$50, COLUMN()-1, Sheet1!$AL$1:$AL$50, 32-ROW())>0, 999, IF(AND(COLUMN()-1=Sheet1!$AF$4, 32-ROW()=Sheet1!$AG$4), 0, MIN(A11, B11, C11, A12, C12, A13, B13, C13) + 1))) -> 999 | C12: =IF(Sheet1!$AG$1=1, IF(AND(COLUMN()-1=Sheet1!$AF$4, 32-ROW()=Sheet1!$AG$4), 0, 999), IF(COUNTIFS(Sheet1!$AK$1:$AK$50, COLUMN()-1, Sheet1!$AL$1:$AL$50, 32-ROW())>0, 999, IF(AND(COLUMN()-1=Sheet1!$AF$4, 32-ROW()=Sheet1!$AG$4), 0, MIN(B11, C11, D11, B12, D12, B13, C13, D13) + 1))) -> 999 | D12: =IF(Sheet1!$AG$1=1, IF(AND(COLUMN()-1=Sheet1!$AF$4, 32-ROW()=Sheet1!$AG$4), 0, 999), IF(COUNTIFS(Sheet1!$AK$1:$AK$50, COLUMN()-1, Sheet1!$AL$1:$AL$50, 32-ROW())>0, 999, IF(AND(COLUMN()-1=Sheet1!$AF$4, 32-ROW()=Sheet1!$AG$4), 0, MIN(C11, D11, E11, C12, E12, C13, D13, E13) + 1))) -> 999 | E12: =IF(Sheet1!$AG$1=1, IF(AND(COLUMN()-1=Sheet1!$AF$4, 32-ROW()=Sheet1!$AG$4), 0, 999), IF(COUNTIFS(Sheet1!$AK$1:$AK$50, COLUMN()-1, Sheet1!$AL$1:$AL$50, 32-ROW())>0, 999, IF(AND(COLUMN()-1=Sheet1!$AF$4, 32-ROW()=Sheet1!$AG$4), 0, MIN(D11, E11, F11, D12, F12, D13, E13, F13) + 1))) -> 999 | F12: =IF(Sheet1!$AG$1=1, IF(AND(COLUMN()-1=Sheet1!$AF$4, 32-ROW()=Sheet1!$AG$4), 0, 999), IF(COUNTIFS(Sheet1!$AK$1:$AK$50, COLUMN()-1, Sheet1!$AL$1:$AL$50, 32-ROW())>0, 999, IF(AND(COLUMN()-1=Sheet1!$AF$4, 32-ROW()=Sheet1!$AG$4), 0, MIN(E11, F11, G11, E12, G12, E13, F13, G13) + 1))) -> 999 | G12: =IF(Sheet1!$AG$1=1, IF(AND(COLUMN()-1=Sheet1!$AF$4, 32-ROW()=Sheet1!$AG$4), 0, 999), IF(COUNTIFS(Sheet1!$AK$1:$AK$50, COLUMN()-1, Sheet1!$AL$1:$AL$50, 32-ROW())>0, 999, IF(AND(COLUMN()-1=Sheet1!$AF$4, 32-ROW()=Sheet1!$AG$4), 0, MIN(F11, G11, H11, F12, H12, F13, G13, H13) + 1))) -> 999 | H12: =IF(Sheet1!$AG$1=1, IF(AND(COLUMN()-1=Sheet1!$AF$4, 32-ROW()=Sheet1!$AG$4), 0, 999), IF(COUNTIFS(Sheet1!$AK$1:$AK$50, COLUMN()-1, Sheet1!$AL$1:$AL$50, 32-ROW())>0, 999, IF(AND(COLUMN()-1=Sheet1!$AF$4, 32-ROW()=Sheet1!$AG$4), 0, MIN(G11, H11, I11, G12, I12, G13, H13, I13) + 1))) -> 999 | I12: =IF(Sheet1!$AG$1=1, IF(AND(COLUMN()-1=Sheet1!$AF$4, 32-ROW()=Sheet1!$AG$4), 0, 999), IF(COUNTIFS(Sheet1!$AK$1:$AK$50, COLUMN()-1, Sheet1!$AL$1:$AL$50, 32-ROW())>0, 999, IF(AND(COLUMN()-1=Sheet1!$AF$4, 32-ROW()=Sheet1!$AG$4), 0, MIN(H11, I11, J11, H12, J12, H13, I13, J13) + 1))) -> 999 | ... AE12: =IF(Sheet1!$AG$1=1, IF(AND(COLUMN()-1=Sheet1!$AF$4, 32-ROW()=Sheet1!$AG$4), 0, 999), IF(COUNTIFS(Sheet1!$AK$1:$AK$50, COLUMN()-1, Sheet1!$AL$1:$AL$50, 32-ROW())>0, 999, IF(AND(COLUMN()-1=Sheet1!$AF$4, 32-ROW()=Sheet1!$AG$4), 0, MIN(AD11, AE11, AF11, AD12, AF12, AD13, AE13, AF13) + 1))) -> 999 | AF12: 999
A13: 999 | B13: =IF(Sheet1!$AG$1=1, IF(AND(COLUMN()-1=Sheet1!$AF$4, 32-ROW()=Sheet1!$AG$4), 0, 999), IF(COUNTIFS(Sheet1!$AK$1:$AK$50, COLUMN()-1, Sheet1!$AL$1:$AL$50, 32-ROW())>0, 999, IF(AND(COLUMN()-1=Sheet1!$AF$4, 32-ROW()=Sheet1!$AG$4), 0, MIN(A12, B12, C12, A13, C13, A14, B14, C14) + 1))) -> 999 | C13: =IF(Sheet1!$AG$1=1, IF(AND(COLUMN()-1=Sheet1!$AF$4, 32-ROW()=Sheet1!$AG$4), 0, 999), IF(COUNTIFS(Sheet1!$AK$1:$AK$50, COLUMN()-1, Sheet1!$AL$1:$AL$50, 32-ROW())>0, 999, IF(AND(COLUMN()-1=Sheet1!$AF$4, 32-ROW()=Sheet1!$AG$4), 0, MIN(B12, C12, D12, B13, D13, B14, C14, D14) + 1))) -> 999 | D13: =IF(Sheet1!$AG$1=1, IF(AND(COLUMN()-1=Sheet1!$AF$4, 32-ROW()=Sheet1!$AG$4), 0, 999), IF(COUNTIFS(Sheet1!$AK$1:$AK$50, COLUMN()-1, Sheet1!$AL$1:$AL$50, 32-ROW())>0, 999, IF(AND(COLUMN()-1=Sheet1!$AF$4, 32-ROW()=Sheet1!$AG$4), 0, MIN(C12, D12, E12, C13, E13, C14, D14, E14) + 1))) -> 999 | E13: =IF(Sheet1!$AG$1=1, IF(AND(COLUMN()-1=Sheet1!$AF$4, 32-ROW()=Sheet1!$AG$4), 0, 999), IF(COUNTIFS(Sheet1!$AK$1:$AK$50, COLUMN()-1, Sheet1!$AL$1:$AL$50, 32-ROW())>0, 999, IF(AND(COLUMN()-1=Sheet1!$AF$4, 32-ROW()=Sheet1!$AG$4), 0, MIN(D12, E12, F12, D13, F13, D14, E14, F14) + 1))) -> 999 | F13: =IF(Sheet1!$AG$1=1, IF(AND(COLUMN()-1=Sheet1!$AF$4, 32-ROW()=Sheet1!$AG$4), 0, 999), IF(COUNTIFS(Sheet1!$AK$1:$AK$50, COLUMN()-1, Sheet1!$AL$1:$AL$50, 32-ROW())>0, 999, IF(AND(COLUMN()-1=Sheet1!$AF$4, 32-ROW()=Sheet1!$AG$4), 0, MIN(E12, F12, G12, E13, G13, E14, F14, G14) + 1))) -> 999 | G13: =IF(Sheet1!$AG$1=1, IF(AND(COLUMN()-1=Sheet1!$AF$4, 32-ROW()=Sheet1!$AG$4), 0, 999), IF(COUNTIFS(Sheet1!$AK$1:$AK$50, COLUMN()-1, Sheet1!$AL$1:$AL$50, 32-ROW())>0, 999, IF(AND(COLUMN()-1=Sheet1!$AF$4, 32-ROW()=Sheet1!$AG$4), 0, MIN(F12, G12, H12, F13, H13, F14, G14, H14) + 1))) -> 999 | H13: =IF(Sheet1!$AG$1=1, IF(AND(COLUMN()-1=Sheet1!$AF$4, 32-ROW()=Sheet1!$AG$4), 0, 999), IF(COUNTIFS(Sheet1!$AK$1:$AK$50, COLUMN()-1, Sheet1!$AL$1:$AL$50, 32-ROW())>0, 999, IF(AND(COLUMN()-1=Sheet1!$AF$4, 32-ROW()=Sheet1!$AG$4), 0, MIN(G12, H12, I12, G13, I13, G14, H14, I14) + 1))) -> 999 | I13: =IF(Sheet1!$AG$1=1, IF(AND(COLUMN()-1=Sheet1!$AF$4, 32-ROW()=Sheet1!$AG$4), 0, 999), IF(COUNTIFS(Sheet1!$AK$1:$AK$50, COLUMN()-1, Sheet1!$AL$1:$AL$50, 32-ROW())>0, 999, IF(AND(COLUMN()-1=Sheet1!$AF$4, 32-ROW()=Sheet1!$AG$4), 0, MIN(H12, I12, J12, H13, J13, H14, I14, J14) + 1))) -> 999 | ... AE13: =IF(Sheet1!$AG$1=1, IF(AND(COLUMN()-1=Sheet1!$AF$4, 32-ROW()=Sheet1!$AG$4), 0, 999), IF(COUNTIFS(Sheet1!$AK$1:$AK$50, COLUMN()-1, Sheet1!$AL$1:$AL$50, 32-ROW())>0, 999, IF(AND(COLUMN()-1=Sheet1!$AF$4, 32-ROW()=Sheet1!$AG$4), 0, MIN(AD12, AE12, AF12, AD13, AF13, AD14, AE14, AF14) + 1))) -> 999 | AF13: 999
... A31: 999 | B31: =IF(Sheet1!$AG$1=1, IF(AND(COLUMN()-1=Sheet1!$AF$4, 32-ROW()=Sheet1!$AG$4), 0, 999), IF(COUNTIFS(Sheet1!$AK$1:$AK$50, COLUMN()-1, Sheet1!$AL$1:$AL$50, 32-ROW())>0, 999, IF(AND(COLUMN()-1=Sheet1!$AF$4, 32-ROW()=Sheet1!$AG$4), 0, MIN(A30, B30, C30, A31, C31, A32, B32, C32) + 1))) -> 999 | C31: =IF(Sheet1!$AG$1=1, IF(AND(COLUMN()-1=Sheet1!$AF$4, 32-ROW()=Sheet1!$AG$4), 0, 999), IF(COUNTIFS(Sheet1!$AK$1:$AK$50, COLUMN()-1, Sheet1!$AL$1:$AL$50, 32-ROW())>0, 999, IF(AND(COLUMN()-1=Sheet1!$AF$4, 32-ROW()=Sheet1!$AG$4), 0, MIN(B30, C30, D30, B31, D31, B32, C32, D32) + 1))) -> 999 | D31: =IF(Sheet1!$AG$1=1, IF(AND(COLUMN()-1=Sheet1!$AF$4, 32-ROW()=Sheet1!$AG$4), 0, 999), IF(COUNTIFS(Sheet1!$AK$1:$AK$50, COLUMN()-1, Sheet1!$AL$1:$AL$50, 32-ROW())>0, 999, IF(AND(COLUMN()-1=Sheet1!$AF$4, 32-ROW()=Sheet1!$AG$4), 0, MIN(C30, D30, E30, C31, E31, C32, D32, E32) + 1))) -> 999 | E31: =IF(Sheet1!$AG$1=1, IF(AND(COLUMN()-1=Sheet1!$AF$4, 32-ROW()=Sheet1!$AG$4), 0, 999), IF(COUNTIFS(Sheet1!$AK$1:$AK$50, COLUMN()-1, Sheet1!$AL$1:$AL$50, 32-ROW())>0, 999, IF(AND(COLUMN()-1=Sheet1!$AF$4, 32-ROW()=Sheet1!$AG$4), 0, MIN(D30, E30, F30, D31, F31, D32, E32, F32) + 1))) -> 999 | F31: =IF(Sheet1!$AG$1=1, IF(AND(COLUMN()-1=Sheet1!$AF$4, 32-ROW()=Sheet1!$AG$4), 0, 999), IF(COUNTIFS(Sheet1!$AK$1:$AK$50, COLUMN()-1, Sheet1!$AL$1:$AL$50, 32-ROW())>0, 999, IF(AND(COLUMN()-1=Sheet1!$AF$4, 32-ROW()=Sheet1!$AG$4), 0, MIN(E30, F30, G30, E31, G31, E32, F32, G32) + 1))) -> 999 | G31: =IF(Sheet1!$AG$1=1, IF(AND(COLUMN()-1=Sheet1!$AF$4, 32-ROW()=Sheet1!$AG$4), 0, 999), IF(COUNTIFS(Sheet1!$AK$1:$AK$50, COLUMN()-1, Sheet1!$AL$1:$AL$50, 32-ROW())>0, 999, IF(AND(COLUMN()-1=Sheet1!$AF$4, 32-ROW()=Sheet1!$AG$4), 0, MIN(F30, G30, H30, F31, H31, F32, G32, H32) + 1))) -> 999 | H31: =IF(Sheet1!$AG$1=1, IF(AND(COLUMN()-1=Sheet1!$AF$4, 32-ROW()=Sheet1!$AG$4), 0, 999), IF(COUNTIFS(Sheet1!$AK$1:$AK$50, COLUMN()-1, Sheet1!$AL$1:$AL$50, 32-ROW())>0, 999, IF(AND(COLUMN()-1=Sheet1!$AF$4, 32-ROW()=Sheet1!$AG$4), 0, MIN(G30, H30, I30, G31, I31, G32, H32, I32) + 1))) -> 999 | I31: =IF(Sheet1!$AG$1=1, IF(AND(COLUMN()-1=Sheet1!$AF$4, 32-ROW()=Sheet1!$AG$4), 0, 999), IF(COUNTIFS(Sheet1!$AK$1:$AK$50, COLUMN()-1, Sheet1!$AL$1:$AL$50, 32-ROW())>0, 999, IF(AND(COLUMN()-1=Sheet1!$AF$4, 32-ROW()=Sheet1!$AG$4), 0, MIN(H30, I30, J30, H31, J31, H32, I32, J32) + 1))) -> 999 | ... AE31: =IF(Sheet1!$AG$1=1, IF(AND(COLUMN()-1=Sheet1!$AF$4, 32-ROW()=Sheet1!$AG$4), 0, 999), IF(COUNTIFS(Sheet1!$AK$1:$AK$50, COLUMN()-1, Sheet1!$AL$1:$AL$50, 32-ROW())>0, 999, IF(AND(COLUMN()-1=Sheet1!$AF$4, 32-ROW()=Sheet1!$AG$4), 0, MIN(AD30, AE30, AF30, AD31, AF31, AD32, AE32, AF32) + 1))) -> 999 | AF31: 999
A32: 999 | B32: 999 | C32: 999 | D32: 999 | E32: 999 | F32: 999 | G32: 999 | H32: 999 | I32: 999 | J32: 999 | K32: 999 | L32: 999 | M32: 999 | N32: 999 | O32: 999 | P32: 999 | Q32: 999 | R32: 999 | S32: 999 | T32: 999 | U32: 999 | V32: 999 | W32: 999 | X32: 999 | Y32: 999 | Z32: 999 | AA32: 999 | AB32: 999 | AC32: 999 | AD32: 999 | AE32: 999 | AF32: 999

Sheet Sheet3
A1: 99999 | B1: 99999 | C1: 99999 | D1: 99999 | E1: 99999 | F1: 99999 | G1: 99999 | H1: 99999 | I1: 99999 | J1: 99999 | K1: 99999 | L1: 99999 | M1: 99999 | N1: 99999 | O1: 99999 | P1: 99999 | Q1: 99999 | R1: 99999 | S1: 99999 | T1: 99999 | U1: 99999 | V1: 99999 | W1: 99999 | X1: 99999 | Y1: 99999 | Z1: 99999 | AA1: 99999 | AB1: 99999 | AC1: 99999 | AD1: 99999 | AE1: 99999 | AF1: 99999
A2: 99999 | B2: {=IF(AND(COLUMN()-1=Sheet1!$AF$4, 32-ROW()=Sheet1!$AG$4), 0, IF(COUNTIFS(Sheet1!$AK$2:$AK$51, COLUMN()-1, Sheet1!$AL$2:$AL$51, 32-ROW())>0, 99999, Sheet1!$AR$1*((COLUMN()-1-Sheet1!$AF$4)^2+(32-ROW()-Sheet1!$AG$4)^2) + Sheet1!$AR$2*SUMPRODUCT((Sheet1!$AK$2:$AK$51<>"")*(1/(((COLUMN()-1-Sheet1!$AK$2:$AK$51)^2+(32-ROW()-Sheet1!$AL$2:$AL$51)^2)+0.1)))))} -> 99999 | C2: {=IF(AND(COLUMN()-1=Sheet1!$AF$4, 32-ROW()=Sheet1!$AG$4), 0, IF(COUNTIFS(Sheet1!$AK$2:$AK$51, COLUMN()-1, Sheet1!$AL$2:$AL$51, 32-ROW())>0, 99999, Sheet1!$AR$1*((COLUMN()-1-Sheet1!$AF$4)^2+(32-ROW()-Sheet1!$AG$4)^2) + Sheet1!$AR$2*SUMPRODUCT((Sheet1!$AK$2:$AK$51<>"")*(1/(((COLUMN()-1-Sheet1!$AK$2:$AK$51)^2+(32-ROW()-Sheet1!$AL$2:$AL$51)^2)+0.1)))))} -> 11215.945 | D2: {=IF(AND(COLUMN()-1=Sheet1!$AF$4, 32-ROW()=Sheet1!$AG$4), 0, IF(COUNTIFS(Sheet1!$AK$2:$AK$51, COLUMN()-1, Sheet1!$AL$2:$AL$51, 32-ROW())>0, 99999, Sheet1!$AR$1*((COLUMN()-1-Sheet1!$AF$4)^2+(32-ROW()-Sheet1!$AG$4)^2) + Sheet1!$AR$2*SUMPRODUCT((Sheet1!$AK$2:$AK$51<>"")*(1/(((COLUMN()-1-Sheet1!$AK$2:$AK$51)^2+(32-ROW()-Sheet1!$AL$2:$AL$51)^2)+0.1)))))} -> 4613.577 | E2: {=IF(AND(COLUMN()-1=Sheet1!$AF$4, 32-ROW()=Sheet1!$AG$4), 0, IF(COUNTIFS(Sheet1!$AK$2:$AK$51, COLUMN()-1, Sheet1!$AL$2:$AL$51, 32-ROW())>0, 99999, Sheet1!$AR$1*((COLUMN()-1-Sheet1!$AF$4)^2+(32-ROW()-Sheet1!$AG$4)^2) + Sheet1!$AR$2*SUMPRODUCT((Sheet1!$AK$2:$AK$51<>"")*(1/(((COLUMN()-1-Sheet1!$AK$2:$AK$51)^2+(32-ROW()-Sheet1!$AL$2:$AL$51)^2)+0.1)))))} -> 3314.4948 | F2: {=IF(AND(COLUMN()-1=Sheet1!$AF$4, 32-ROW()=Sheet1!$AG$4), 0, IF(COUNTIFS(Sheet1!$AK$2:$AK$51, COLUMN()-1, Sheet1!$AL$2:$AL$51, 32-ROW())>0, 99999, Sheet1!$AR$1*((COLUMN()-1-Sheet1!$AF$4)^2+(32-ROW()-Sheet1!$AG$4)^2) + Sheet1!$AR$2*SUMPRODUCT((Sheet1!$AK$2:$AK$51<>"")*(1/(((COLUMN()-1-Sheet1!$AK$2:$AK$51)^2+(32-ROW()-Sheet1!$AL$2:$AL$51)^2)+0.1)))))} -> 2865.7842 | G2: {=IF(AND(COLUMN()-1=Sheet1!$AF$4, 32-ROW()=Sheet1!$AG$4), 0, IF(COUNTIFS(Sheet1!$AK$2:$AK$51, COLUMN()-1, Sheet1!$AL$2:$AL$51, 32-ROW())>0, 99999, Sheet1!$AR$1*((COLUMN()-1-Sheet1!$AF$4)^2+(32-ROW()-Sheet1!$AG$4)^2) + Sheet1!$AR$2*SUMPRODUCT((Sheet1!$AK$2:$AK$51<>"")*(1/(((COLUMN()-1-Sheet1!$AK$2:$AK$51)^2+(32-ROW()-Sheet1!$AL$2:$AL$51)^2)+0.1)))))} -> 2657.5705 | H2: {=IF(AND(COLUMN()-1=Sheet1!$AF$4, 32-ROW()=Sheet1!$AG$4), 0, IF(COUNTIFS(Sheet1!$AK$2:$AK$51, COLUMN()-1, Sheet1!$AL$2:$AL$51, 32-ROW())>0, 99999, Sheet1!$AR$1*((COLUMN()-1-Sheet1!$AF$4)^2+(32-ROW()-Sheet1!$AG$4)^2) + Sheet1!$AR$2*SUMPRODUCT((Sheet1!$AK$2:$AK$51<>"")*(1/(((COLUMN()-1-Sheet1!$AK$2:$AK$51)^2+(32-ROW()-Sheet1!$AL$2:$AL$51)^2)+0.1)))))} -> 2534.2115 | I2: {=IF(AND(COLUMN()-1=Sheet1!$AF$4, 32-ROW()=Sheet1!$AG$4), 0, IF(COUNTIFS(Sheet1!$AK$2:$AK$51, COLUMN()-1, Sheet1!$AL$2:$AL$51, 32-ROW())>0, 99999, Sheet1!$AR$1*((COLUMN()-1-Sheet1!$AF$4)^2+(32-ROW()-Sheet1!$AG$4)^2) + Sheet1!$AR$2*SUMPRODUCT((Sheet1!$AK$2:$AK$51<>"")*(1/(((COLUMN()-1-Sheet1!$AK$2:$AK$51)^2+(32-ROW()-Sheet1!$AL$2:$AL$51)^2)+0.1)))))} -> 2443.4608 | ... AE2: {=IF(AND(COLUMN()-1=Sheet1!$AF$4, 32-ROW()=Sheet1!$AG$4), 0, IF(COUNTIFS(Sheet1!$AK$2:$AK$51, COLUMN()-1, Sheet1!$AL$2:$AL$51, 32-ROW())>0, 99999, Sheet1!$AR$1*((COLUMN()-1-Sheet1!$AF$4)^2+(32-ROW()-Sheet1!$AG$4)^2) + Sheet1!$AR$2*SUMPRODUCT((Sheet1!$AK$2:$AK$51<>"")*(1/(((COLUMN()-1-Sheet1!$AK$2:$AK$51)^2+(32-ROW()-Sheet1!$AL$2:$AL$51)^2)+0.1)))))} -> 0 | AF2: 99999
A3: 99999 | B3: {=IF(AND(COLUMN()-1=Sheet1!$AF$4, 32-ROW()=Sheet1!$AG$4), 0, IF(COUNTIFS(Sheet1!$AK$2:$AK$51, COLUMN()-1, Sheet1!$AL$2:$AL$51, 32-ROW())>0, 99999, Sheet1!$AR$1*((COLUMN()-1-Sheet1!$AF$4)^2+(32-ROW()-Sheet1!$AG$4)^2) + Sheet1!$AR$2*SUMPRODUCT((Sheet1!$AK$2:$AK$51<>"")*(1/(((COLUMN()-1-Sheet1!$AK$2:$AK$51)^2+(32-ROW()-Sheet1!$AL$2:$AL$51)^2)+0.1)))))} -> 11361.765 | C3: {=IF(AND(COLUMN()-1=Sheet1!$AF$4, 32-ROW()=Sheet1!$AG$4), 0, IF(COUNTIFS(Sheet1!$AK$2:$AK$51, COLUMN()-1, Sheet1!$AL$2:$AL$51, 32-ROW())>0, 99999, Sheet1!$AR$1*((COLUMN()-1-Sheet1!$AF$4)^2+(32-ROW()-Sheet1!$AG$4)^2) + Sheet1!$AR$2*SUMPRODUCT((Sheet1!$AK$2:$AK$51<>"")*(1/(((COLUMN()-1-Sheet1!$AK$2:$AK$51)^2+(32-ROW()-Sheet1!$AL$2:$AL$51)^2)+0.1)))))} -> 7130.7694 | D3: {=IF(AND(COLUMN()-1=Sheet1!$AF$4, 32-ROW()=Sheet1!$AG$4), 0, IF(COUNTIFS(Sheet1!$AK$2:$AK$51, COLUMN()-1, Sheet1!$AL$2:$AL$51, 32-ROW())>0, 99999, Sheet1!$AR$1*((COLUMN()-1-Sheet1!$AF$4)^2+(32-ROW()-Sheet1!$AG$4)^2) + Sheet1!$AR$2*SUMPRODUCT((Sheet1!$AK$2:$AK$51<>"")*(1/(((COLUMN()-1-Sheet1!$AK$2:$AK$51)^2+(32-ROW()-Sheet1!$AL$2:$AL$51)^2)+0.1)))))} -> 4420.4442 | E3: {=IF(AND(COLUMN()-1=Sheet1!$AF$4, 32-ROW()=Sheet1!$AG$4), 0, IF(COUNTIFS(Sheet1!$AK$2:$AK$51, COLUMN()-1, Sheet1!$AL$2:$AL$51, 32-ROW())>0, 99999, Sheet1!$AR$1*((COLUMN()-1-Sheet1!$AF$4)^2+(32-ROW()-Sheet1!$AG$4)^2) + Sheet1!$AR$2*SUMPRODUCT((Sheet1!$AK$2:$AK$51<>"")*(1/(((COLUMN()-1-Sheet1!$AK$2:$AK$51)^2+(32-ROW()-Sheet1!$AL$2:$AL$51)^2)+0.1)))))} -> 3523.857 | F3: {=IF(AND(COLUMN()-1=Sheet1!$AF$4, 32-ROW()=Sheet1!$AG$4), 0, IF(COUNTIFS(Sheet1!$AK$2:$AK$51, COLUMN()-1, Sheet1!$AL$2:$AL$51, 32-ROW())>0, 99999, Sheet1!$AR$1*((COLUMN()-1-Sheet1!$AF$4)^2+(32-ROW()-Sheet1!$AG$4)^2) + Sheet1!$AR$2*SUMPRODUCT((Sheet1!$AK$2:$AK$51<>"")*(1/(((COLUMN()-1-Sheet1!$AK$2:$AK$51)^2+(32-ROW()-Sheet1!$AL$2:$AL$51)^2)+0.1)))))} -> 3172.9352 | G3: {=IF(AND(COLUMN()-1=Sheet1!$AF$4, 32-ROW()=Sheet1!$AG$4), 0, IF(COUNTIFS(Sheet1!$AK$2:$AK$51, COLUMN()-1, Sheet1!$AL$2:$AL$51, 32-ROW())>0, 99999, Sheet1!$AR$1*((COLUMN()-1-Sheet1!$AF$4)^2+(32-ROW()-Sheet1!$AG$4)^2) + Sheet1!$AR$2*SUMPRODUCT((Sheet1!$AK$2:$AK$51<>"")*(1/(((COLUMN()-1-Sheet1!$AK$2:$AK$51)^2+(32-ROW()-Sheet1!$AL$2:$AL$51)^2)+0.1)))))} -> 3002.8556 | H3: {=IF(AND(COLUMN()-1=Sheet1!$AF$4, 32-ROW()=Sheet1!$AG$4), 0, IF(COUNTIFS(Sheet1!$AK$2:$AK$51, COLUMN()-1, Sheet1!$AL$2:$AL$51, 32-ROW())>0, 99999, Sheet1!$AR$1*((COLUMN()-1-Sheet1!$AF$4)^2+(32-ROW()-Sheet1!$AG$4)^2) + Sheet1!$AR$2*SUMPRODUCT((Sheet1!$AK$2:$AK$51<>"")*(1/(((COLUMN()-1-Sheet1!$AK$2:$AK$51)^2+(32-ROW()-Sheet1!$AL$2:$AL$51)^2)+0.1)))))} -> 2891.2346 | I3: {=IF(AND(COLUMN()-1=Sheet1!$AF$4, 32-ROW()=Sheet1!$AG$4), 0, IF(COUNTIFS(Sheet1!$AK$2:$AK$51, COLUMN()-1, Sheet1!$AL$2:$AL$51, 32-ROW())>0, 99999, Sheet1!$AR$1*((COLUMN()-1-Sheet1!$AF$4)^2+(32-ROW()-Sheet1!$AG$4)^2) + Sheet1!$AR$2*SUMPRODUCT((Sheet1!$AK$2:$AK$51<>"")*(1/(((COLUMN()-1-Sheet1!$AK$2:$AK$51)^2+(32-ROW()-Sheet1!$AL$2:$AL$51)^2)+0.1)))))} -> 2791.8172 | ... AE3: {=IF(AND(COLUMN()-1=Sheet1!$AF$4, 32-ROW()=Sheet1!$AG$4), 0, IF(COUNTIFS(Sheet1!$AK$2:$AK$51, COLUMN()-1, Sheet1!$AL$2:$AL$51, 32-ROW())>0, 99999, Sheet1!$AR$1*((COLUMN()-1-Sheet1!$AF$4)^2+(32-ROW()-Sheet1!$AG$4)^2) + Sheet1!$AR$2*SUMPRODUCT((Sheet1!$AK$2:$AK$51<>"")*(1/(((COLUMN()-1-Sheet1!$AK$2:$AK$51)^2+(32-ROW()-Sheet1!$AL$2:$AL$51)^2)+0.1)))))} -> 1098.2732 | AF3: 99999
A4: 99999 | B4: {=IF(AND(COLUMN()-1=Sheet1!$AF$4, 32-ROW()=Sheet1!$AG$4), 0, IF(COUNTIFS(Sheet1!$AK$2:$AK$51, COLUMN()-1, Sheet1!$AL$2:$AL$51, 32-ROW())>0, 99999, Sheet1!$AR$1*((COLUMN()-1-Sheet1!$AF$4)^2+(32-ROW()-Sheet1!$AG$4)^2) + Sheet1!$AR$2*SUMPRODUCT((Sheet1!$AK$2:$AK$51<>"")*(1/(((COLUMN()-1-Sheet1!$AK$2:$AK$51)^2+(32-ROW()-Sheet1!$AL$2:$AL$51)^2)+0.1)))))} -> 4983.0564 | C4: {=IF(AND(COLUMN()-1=Sheet1!$AF$4, 32-ROW()=Sheet1!$AG$4), 0, IF(COUNTIFS(Sheet1!$AK$2:$AK$51, COLUMN()-1, Sheet1!$AL$2:$AL$51, 32-ROW())>0, 99999, Sheet1!$AR$1*((COLUMN()-1-Sheet1!$AF$4)^2+(32-ROW()-Sheet1!$AG$4)^2) + Sheet1!$AR$2*SUMPRODUCT((Sheet1!$AK$2:$AK$51<>"")*(1/(((COLUMN()-1-Sheet1!$AK$2:$AK$51)^2+(32-ROW()-Sheet1!$AL$2:$AL$51)^2)+0.1)))))} -> 4685.981 | D4: {=IF(AND(COLUMN()-1=Sheet1!$AF$4, 32-ROW()=Sheet1!$AG$4), 0, IF(COUNTIFS(Sheet1!$AK$2:$AK$51, COLUMN()-1, Sheet1!$AL$2:$AL$51, 32-ROW())>0, 99999, Sheet1!$AR$1*((COLUMN()-1-Sheet1!$AF$4)^2+(32-ROW()-Sheet1!$AG$4)^2) + Sheet1!$AR$2*SUMPRODUCT((Sheet1!$AK$2:$AK$51<>"")*(1/(((COLUMN()-1-Sheet1!$AK$2:$AK$51)^2+(32-ROW()-Sheet1!$AL$2:$AL$51)^2)+0.1)))))} -> 4121.764 | E4: {=IF(AND(COLUMN()-1=Sheet1!$AF$4, 32-ROW()=Sheet1!$AG$4), 0, IF(COUNTIFS(Sheet1!$AK$2:$AK$51, COLUMN()-1, Sheet1!$AL$2:$AL$51, 32-ROW())>0, 99999, Sheet1!$AR$1*((COLUMN()-1-Sheet1!$AF$4)^2+(32-ROW()-Sheet1!$AG$4)^2) + Sheet1!$AR$2*SUMPRODUCT((Sheet1!$AK$2:$AK$51<>"")*(1/(((COLUMN()-1-Sheet1!$AK$2:$AK$51)^2+(32-ROW()-Sheet1!$AL$2:$AL$51)^2)+0.1)))))} -> 3772.1972 | F4: {=IF(AND(COLUMN()-1=Sheet1!$AF$4, 32-ROW()=Sheet1!$AG$4), 0, IF(COUNTIFS(Sheet1!$AK$2:$AK$51, COLUMN()-1, Sheet1!$AL$2:$AL$51, 32-ROW())>0, 99999, Sheet1!$AR$1*((COLUMN()-1-Sheet1!$AF$4)^2+(32-ROW()-Sheet1!$AG$4)^2) + Sheet1!$AR$2*SUMPRODUCT((Sheet1!$AK$2:$AK$51<>"")*(1/(((COLUMN()-1-Sheet1!$AK$2:$AK$51)^2+(32-ROW()-Sheet1!$AL$2:$AL$51)^2)+0.1)))))} -> 3597.291 | G4: {=IF(AND(COLUMN()-1=Sheet1!$AF$4, 32-ROW()=Sheet1!$AG$4), 0, IF(COUNTIFS(Sheet1!$AK$2:$AK$51, COLUMN()-1, Sheet1!$AL$2:$AL$51, 32-ROW())>0, 99999, Sheet1!$AR$1*((COLUMN()-1-Sheet1!$AF$4)^2+(32-ROW()-Sheet1!$AG$4)^2) + Sheet1!$AR$2*SUMPRODUCT((Sheet1!$AK$2:$AK$51<>"")*(1/(((COLUMN()-1-Sheet1!$AK$2:$AK$51)^2+(32-ROW()-Sheet1!$AL$2:$AL$51)^2)+0.1)))))} -> 3507.6976 | H4: {=IF(AND(COLUMN()-1=Sheet1!$AF$4, 32-ROW()=Sheet1!$AG$4), 0, IF(COUNTIFS(Sheet1!$AK$2:$AK$51, COLUMN()-1, Sheet1!$AL$2:$AL$51, 32-ROW())>0, 99999, Sheet1!$AR$1*((COLUMN()-1-Sheet1!$AF$4)^2+(32-ROW()-Sheet1!$AG$4)^2) + Sheet1!$AR$2*SUMPRODUCT((Sheet1!$AK$2:$AK$51<>"")*(1/(((COLUMN()-1-Sheet1!$AK$2:$AK$51)^2+(32-ROW()-Sheet1!$AL$2:$AL$51)^2)+0.1)))))} -> 3423.172 | I4: {=IF(AND(COLUMN()-1=Sheet1!$AF$4, 32-ROW()=Sheet1!$AG$4), 0, IF(COUNTIFS(Sheet1!$AK$2:$AK$51, COLUMN()-1, Sheet1!$AL$2:$AL$51, 32-ROW())>0, 99999, Sheet1!$AR$1*((COLUMN()-1-Sheet1!$AF$4)^2+(32-ROW()-Sheet1!$AG$4)^2) + Sheet1!$AR$2*SUMPRODUCT((Sheet1!$AK$2:$AK$51<>"")*(1/(((COLUMN()-1-Sheet1!$AK$2:$AK$51)^2+(32-ROW()-Sheet1!$AL$2:$AL$51)^2)+0.1)))))} -> 3297.0042 | ... AE4: {=IF(AND(COLUMN()-1=Sheet1!$AF$4, 32-ROW()=Sheet1!$AG$4), 0, IF(COUNTIFS(Sheet1!$AK$2:$AK$51, COLUMN()-1, Sheet1!$AL$2:$AL$51, 32-ROW())>0, 99999, Sheet1!$AR$1*((COLUMN()-1-Sheet1!$AF$4)^2+(32-ROW()-Sheet1!$AG$4)^2) + Sheet1!$AR$2*SUMPRODUCT((Sheet1!$AK$2:$AK$51<>"")*(1/(((COLUMN()-1-Sheet1!$AK$2:$AK$51)^2+(32-ROW()-Sheet1!$AL$2:$AL$51)^2)+0.1)))))} -> 1233.6296 | AF4: 99999
A5: 99999 | B5: {=IF(AND(COLUMN()-1=Sheet1!$AF$4, 32-ROW()=Sheet1!$AG$4), 0, IF(COUNTIFS(Sheet1!$AK$2:$AK$51, COLUMN()-1, Sheet1!$AL$2:$AL$51, 32-ROW())>0, 99999, Sheet1!$AR$1*((COLUMN()-1-Sheet1!$AF$4)^2+(32-ROW()-Sheet1!$AG$4)^2) + Sheet1!$AR$2*SUMPRODUCT((Sheet1!$AK$2:$AK$51<>"")*(1/(((COLUMN()-1-Sheet1!$AK$2:$AK$51)^2+(32-ROW()-Sheet1!$AL$2:$AL$51)^2)+0.1)))))} -> 4041.663 | C5: {=IF(AND(COLUMN()-1=Sheet1!$AF$4, 32-ROW()=Sheet1!$AG$4), 0, IF(COUNTIFS(Sheet1!$AK$2:$AK$51, COLUMN()-1, Sheet1!$AL$2:$AL$51, 32-ROW())>0, 99999, Sheet1!$AR$1*((COLUMN()-1-Sheet1!$AF$4)^2+(32-ROW()-Sheet1!$AG$4)^2) + Sheet1!$AR$2*SUMPRODUCT((Sheet1!$AK$2:$AK$51<>"")*(1/(((COLUMN()-1-Sheet1!$AK$2:$AK$51)^2+(32-ROW()-Sheet1!$AL$2:$AL$51)^2)+0.1)))))} -> 4299.891 | D5: {=IF(AND(COLUMN()-1=Sheet1!$AF$4, 32-ROW()=Sheet1!$AG$4), 0, IF(COUNTIFS(Sheet1!$AK$2:$AK$51, COLUMN()-1, Sheet1!$AL$2:$AL$51, 32-ROW())>0, 99999, Sheet1!$AR$1*((COLUMN()-1-Sheet1!$AF$4)^2+(32-ROW()-Sheet1!$AG$4)^2) + Sheet1!$AR$2*SUMPRODUCT((Sheet1!$AK$2:$AK$51<>"")*(1/(((COLUMN()-1-Sheet1!$AK$2:$AK$51)^2+(32-ROW()-Sheet1!$AL$2:$AL$51)^2)+0.1)))))} -> 4381.5681 | E5: {=IF(AND(COLUMN()-1=Sheet1!$AF$4, 32-ROW()=Sheet1!$AG$4), 0, IF(COUNTIFS(Sheet1!$AK$2:$AK$51, COLUMN()-1, Sheet1!$AL$2:$AL$51, 32-ROW())>0, 99999, Sheet1!$AR$1*((COLUMN()-1-Sheet1!$AF$4)^2+(32-ROW()-Sheet1!$AG$4)^2) + Sheet1!$AR$2*SUMPRODUCT((Sheet1!$AK$2:$AK$51<>"")*(1/(((COLUMN()-1-Sheet1!$AK$2:$AK$51)^2+(32-ROW()-Sheet1!$AL$2:$AL$51)^2)+0.1)))))} -> 4338.3018 | F5: {=IF(AND(COLUMN()-1=Sheet1!$AF$4, 32-ROW()=Sheet1!$AG$4), 0, IF(COUNTIFS(Sheet1!$AK$2:$AK$51, COLUMN()-1, Sheet1!$AL$2:$AL$51, 32-ROW())>0, 99999, Sheet1!$AR$1*((COLUMN()-1-Sheet1!$AF$4)^2+(32-ROW()-Sheet1!$AG$4)^2) + Sheet1!$AR$2*SUMPRODUCT((Sheet1!$AK$2:$AK$51<>"")*(1/(((COLUMN()-1-Sheet1!$AK$2:$AK$51)^2+(32-ROW()-Sheet1!$AL$2:$AL$51)^2)+0.1)))))} -> 4312.379 | G5: {=IF(AND(COLUMN()-1=Sheet1!$AF$4, 32-ROW()=Sheet1!$AG$4), 0, IF(COUNTIFS(Sheet1!$AK$2:$AK$51, COLUMN()-1, Sheet1!$AL$2:$AL$51, 32-ROW())>0, 99999, Sheet1!$AR$1*((COLUMN()-1-Sheet1!$AF$4)^2+(32-ROW()-Sheet1!$AG$4)^2) + Sheet1!$AR$2*SUMPRODUCT((Sheet1!$AK$2:$AK$51<>"")*(1/(((COLUMN()-1-Sheet1!$AK$2:$AK$51)^2+(32-ROW()-Sheet1!$AL$2:$AL$51)^2)+0.1)))))} -> 4365.0274 | H5: {=IF(AND(COLUMN()-1=Sheet1!$AF$4, 32-ROW()=Sheet1!$AG$4), 0, IF(COUNTIFS(Sheet1!$AK$2:$AK$51, COLUMN()-1, Sheet1!$AL$2:$AL$51, 32-ROW())>0, 99999, Sheet1!$AR$1*((COLUMN()-1-Sheet1!$AF$4)^2+(32-ROW()-Sheet1!$AG$4)^2) + Sheet1!$AR$2*SUMPRODUCT((Sheet1!$AK$2:$AK$51<>"")*(1/(((COLUMN()-1-Sheet1!$AK$2:$AK$51)^2+(32-ROW()-Sheet1!$AL$2:$AL$51)^2)+0.1)))))} -> 4349.4345 | I5: {=IF(AND(COLUMN()-1=Sheet1!$AF$4, 32-ROW()=Sheet1!$AG$4), 0, IF(COUNTIFS(Sheet1!$AK$2:$AK$51, COLUMN()-1, Sheet1!$AL$2:$AL$51, 32-ROW())>0, 99999, Sheet1!$AR$1*((COLUMN()-1-Sheet1!$AF$4)^2+(32-ROW()-Sheet1!$AG$4)^2) + Sheet1!$AR$2*SUMPRODUCT((Sheet1!$AK$2:$AK$51<>"")*(1/(((COLUMN()-1-Sheet1!$AK$2:$AK$51)^2+(32-ROW()-Sheet1!$AL$2:$AL$51)^2)+0.1)))))} -> 4126.0133 | ... AE5: {=IF(AND(COLUMN()-1=Sheet1!$AF$4, 32-ROW()=Sheet1!$AG$4), 0, IF(COUNTIFS(Sheet1!$AK$2:$AK$51, COLUMN()-1, Sheet1!$AL$2:$AL$51, 32-ROW())>0, 99999, Sheet1!$AR$1*((COLUMN()-1-Sheet1!$AF$4)^2+(32-ROW()-Sheet1!$AG$4)^2) + Sheet1!$AR$2*SUMPRODUCT((Sheet1!$AK$2:$AK$51<>"")*(1/(((COLUMN()-1-Sheet1!$AK$2:$AK$51)^2+(32-ROW()-Sheet1!$AL$2:$AL$51)^2)+0.1)))))} -> 1395.3985 | AF5: 99999
A6: 99999 | B6: {=IF(AND(COLUMN()-1=Sheet1!$AF$4, 32-ROW()=Sheet1!$AG$4), 0, IF(COUNTIFS(Sheet1!$AK$2:$AK$51, COLUMN()-1, Sheet1!$AL$2:$AL$51, 32-ROW())>0, 99999, Sheet1!$AR$1*((COLUMN()-1-Sheet1!$AF$4)^2+(32-ROW()-Sheet1!$AG$4)^2) + Sheet1!$AR$2*SUMPRODUCT((Sheet1!$AK$2:$AK$51<>"")*(1/(((COLUMN()-1-Sheet1!$AK$2:$AK$51)^2+(32-ROW()-Sheet1!$AL$2:$AL$51)^2)+0.1)))))} -> 4176.9576 | C6: {=IF(AND(COLUMN()-1=Sheet1!$AF$4, 32-ROW()=Sheet1!$AG$4), 0, IF(COUNTIFS(Sheet1!$AK$2:$AK$51, COLUMN()-1, Sheet1!$AL$2:$AL$51, 32-ROW())>0, 99999, Sheet1!$AR$1*((COLUMN()-1-Sheet1!$AF$4)^2+(32-ROW()-Sheet1!$AG$4)^2) + Sheet1!$AR$2*SUMPRODUCT((Sheet1!$AK$2:$AK$51<>"")*(1/(((COLUMN()-1-Sheet1!$AK$2:$AK$51)^2+(32-ROW()-Sheet1!$AL$2:$AL$51)^2)+0.1)))))} -> 5063.1881 | D6: {=IF(AND(COLUMN()-1=Sheet1!$AF$4, 32-ROW()=Sheet1!$AG$4), 0, IF(COUNTIFS(Sheet1!$AK$2:$AK$51, COLUMN()-1, Sheet1!$AL$2:$AL$51, 32-ROW())>0, 99999, Sheet1!$AR$1*((COLUMN()-1-Sheet1!$AF$4)^2+(32-ROW()-Sheet1!$AG$4)^2) + Sheet1!$AR$2*SUMPRODUCT((Sheet1!$AK$2:$AK$51<>"")*(1/(((COLUMN()-1-Sheet1!$AK$2:$AK$51)^2+(32-ROW()-Sheet1!$AL$2:$AL$51)^2)+0.1)))))} -> 5754.9235 | E6: {=IF(AND(COLUMN()-1=Sheet1!$AF$4, 32-ROW()=Sheet1!$AG$4), 0, IF(COUNTIFS(Sheet1!$AK$2:$AK$51, COLUMN()-1, Sheet1!$AL$2:$AL$51, 32-ROW())>0, 99999, Sheet1!$AR$1*((COLUMN()-1-Sheet1!$AF$4)^2+(32-ROW()-Sheet1!$AG$4)^2) + Sheet1!$AR$2*SUMPRODUCT((Sheet1!$AK$2:$AK$51<>"")*(1/(((COLUMN()-1-Sheet1!$AK$2:$AK$51)^2+(32-ROW()-Sheet1!$AL$2:$AL$51)^2)+0.1)))))} -> 5651.0904 | F6: {=IF(AND(COLUMN()-1=Sheet1!$AF$4, 32-ROW()=Sheet1!$AG$4), 0, IF(COUNTIFS(Sheet1!$AK$2:$AK$51, COLUMN()-1, Sheet1!$AL$2:$AL$51, 32-ROW())>0, 99999, Sheet1!$AR$1*((COLUMN()-1-Sheet1!$AF$4)^2+(32-ROW()-Sheet1!$AG$4)^2) + Sheet1!$AR$2*SUMPRODUCT((Sheet1!$AK$2:$AK$51<>"")*(1/(((COLUMN()-1-Sheet1!$AK$2:$AK$51)^2+(32-ROW()-Sheet1!$AL$2:$AL$51)^2)+0.1)))))} -> 5585.8971 | G6: {=IF(AND(COLUMN()-1=Sheet1!$AF$4, 32-ROW()=Sheet1!$AG$4), 0, IF(COUNTIFS(Sheet1!$AK$2:$AK$51, COLUMN()-1, Sheet1!$AL$2:$AL$51, 32-ROW())>0, 99999, Sheet1!$AR$1*((COLUMN()-1-Sheet1!$AF$4)^2+(32-ROW()-Sheet1!$AG$4)^2) + Sheet1!$AR$2*SUMPRODUCT((Sheet1!$AK$2:$AK$51<>"")*(1/(((COLUMN()-1-Sheet1!$AK$2:$AK$51)^2+(32-ROW()-Sheet1!$AL$2:$AL$51)^2)+0.1)))))} -> 6077.6485 | H6: {=IF(AND(COLUMN()-1=Sheet1!$AF$4, 32-ROW()=Sheet1!$AG$4), 0, IF(COUNTIFS(Sheet1!$AK$2:$AK$51, COLUMN()-1, Sheet1!$AL$2:$AL$51, 32-ROW())>0, 99999, Sheet1!$AR$1*((COLUMN()-1-Sheet1!$AF$4)^2+(32-ROW()-Sheet1!$AG$4)^2) + Sheet1!$AR$2*SUMPRODUCT((Sheet1!$AK$2:$AK$51<>"")*(1/(((COLUMN()-1-Sheet1!$AK$2:$AK$51)^2+(32-ROW()-Sheet1!$AL$2:$AL$51)^2)+0.1)))))} -> 6438.2273 | I6: {=IF(AND(COLUMN()-1=Sheet1!$AF$4, 32-ROW()=Sheet1!$AG$4), 0, IF(COUNTIFS(Sheet1!$AK$2:$AK$51, COLUMN()-1, Sheet1!$AL$2:$AL$51, 32-ROW())>0, 99999, Sheet1!$AR$1*((COLUMN()-1-Sheet1!$AF$4)^2+(32-ROW()-Sheet1!$AG$4)^2) + Sheet1!$AR$2*SUMPRODUCT((Sheet1!$AK$2:$AK$51<>"")*(1/(((COLUMN()-1-Sheet1!$AK$2:$AK$51)^2+(32-ROW()-Sheet1!$AL$2:$AL$51)^2)+0.1)))))} -> 5763.1092 | ... AE6: {=IF(AND(COLUMN()-1=Sheet1!$AF$4, 32-ROW()=Sheet1!$AG$4), 0, IF(COUNTIFS(Sheet1!$AK$2:$AK$51, COLUMN()-1, Sheet1!$AL$2:$AL$51, 32-ROW())>0, 99999, Sheet1!$AR$1*((COLUMN()-1-Sheet1!$AF$4)^2+(32-ROW()-Sheet1!$AG$4)^2) + Sheet1!$AR$2*SUMPRODUCT((Sheet1!$AK$2:$AK$51<>"")*(1/(((COLUMN()-1-Sheet1!$AK$2:$AK$51)^2+(32-ROW()-Sheet1!$AL$2:$AL$51)^2)+0.1)))))} -> 1578.1331 | AF6: 99999
A7: 99999 | B7: {=IF(AND(COLUMN()-1=Sheet1!$AF$4, 32-ROW()=Sheet1!$AG$4), 0, IF(COUNTIFS(Sheet1!$AK$2:$AK$51, COLUMN()-1, Sheet1!$AL$2:$AL$51, 32-ROW())>0, 99999, Sheet1!$AR$1*((COLUMN()-1-Sheet1!$AF$4)^2+(32-ROW()-Sheet1!$AG$4)^2) + Sheet1!$AR$2*SUMPRODUCT((Sheet1!$AK$2:$AK$51<>"")*(1/(((COLUMN()-1-Sheet1!$AK$2:$AK$51)^2+(32-ROW()-Sheet1!$AL$2:$AL$51)^2)+0.1)))))} -> 4823.2296 | C7: {=IF(AND(COLUMN()-1=Sheet1!$AF$4, 32-ROW()=Sheet1!$AG$4), 0, IF(COUNTIFS(Sheet1!$AK$2:$AK$51, COLUMN()-1, Sheet1!$AL$2:$AL$51, 32-ROW())>0, 99999, Sheet1!$AR$1*((COLUMN()-1-Sheet1!$AF$4)^2+(32-ROW()-Sheet1!$AG$4)^2) + Sheet1!$AR$2*SUMPRODUCT((Sheet1!$AK$2:$AK$51<>"")*(1/(((COLUMN()-1-Sheet1!$AK$2:$AK$51)^2+(32-ROW()-Sheet1!$AL$2:$AL$51)^2)+0.1)))))} -> 7863.5963 | D7: {=IF(AND(COLUMN()-1=Sheet1!$AF$4, 32-ROW()=Sheet1!$AG$4), 0, IF(COUNTIFS(Sheet1!$AK$2:$AK$51, COLUMN()-1, Sheet1!$AL$2:$AL$51, 32-ROW())>0, 99999, Sheet1!$AR$1*((COLUMN()-1-Sheet1!$AF$4)^2+(32-ROW()-Sheet1!$AG$4)^2) + Sheet1!$AR$2*SUMPRODUCT((Sheet1!$AK$2:$AK$51<>"")*(1/(((COLUMN()-1-Sheet1!$AK$2:$AK$51)^2+(32-ROW()-Sheet1!$AL$2:$AL$51)^2)+0.1)))))} -> 12569.881 | E7: {=IF(AND(COLUMN()-1=Sheet1!$AF$4, 32-ROW()=Sheet1!$AG$4), 0, IF(COUNTIFS(Sheet1!$AK$2:$AK$51, COLUMN()-1, Sheet1!$AL$2:$AL$51, 32-ROW())>0, 99999, Sheet1!$AR$1*((COLUMN()-1-Sheet1!$AF$4)^2+(32-ROW()-Sheet1!$AG$4)^2) + Sheet1!$AR$2*SUMPRODUCT((Sheet1!$AK$2:$AK$51<>"")*(1/(((COLUMN()-1-Sheet1!$AK$2:$AK$51)^2+(32-ROW()-Sheet1!$AL$2:$AL$51)^2)+0.1)))))} -> 8938.7042 | F7: {=IF(AND(COLUMN()-1=Sheet1!$AF$4, 32-ROW()=Sheet1!$AG$4), 0, IF(COUNTIFS(Sheet1!$AK$2:$AK$51, COLUMN()-1, Sheet1!$AL$2:$AL$51, 32-ROW())>0, 99999, Sheet1!$AR$1*((COLUMN()-1-Sheet1!$AF$4)^2+(32-ROW()-Sheet1!$AG$4)^2) + Sheet1!$AR$2*SUMPRODUCT((Sheet1!$AK$2:$AK$51<>"")*(1/(((COLUMN()-1-Sheet1!$AK$2:$AK$51)^2+(32-ROW()-Sheet1!$AL$2:$AL$51)^2)+0.1)))))} -> 7623.2236 | G7: {=IF(AND(COLUMN()-1=Sheet1!$AF$4, 32-ROW()=Sheet1!$AG$4), 0, IF(COUNTIFS(Sheet1!$AK$2:$AK$51, COLUMN()-1, Sheet1!$AL$2:$AL$51, 32-ROW())>0, 99999, Sheet1!$AR$1*((COLUMN()-1-Sheet1!$AF$4)^2+(32-ROW()-Sheet1!$AG$4)^2) + Sheet1!$AR$2*SUMPRODUCT((Sheet1!$AK$2:$AK$51<>"")*(1/(((COLUMN()-1-Sheet1!$AK$2:$AK$51)^2+(32-ROW()-Sheet1!$AL$2:$AL$51)^2)+0.1)))))} -> 10246.617 | H7: {=IF(AND(COLUMN()-1=Sheet1!$AF$4, 32-ROW()=Sheet1!$AG$4), 0, IF(COUNTIFS(Sheet1!$AK$2:$AK$51, COLUMN()-1, Sheet1!$AL$2:$AL$51, 32-ROW())>0, 99999, Sheet1!$AR$1*((COLUMN()-1-Sheet1!$AF$4)^2+(32-ROW()-Sheet1!$AG$4)^2) + Sheet1!$AR$2*SUMPRODUCT((Sheet1!$AK$2:$AK$51<>"")*(1/(((COLUMN()-1-Sheet1!$AK$2:$AK$51)^2+(32-ROW()-Sheet1!$AL$2:$AL$51)^2)+0.1)))))} -> 14739.152 | I7: {=IF(AND(COLUMN()-1=Sheet1!$AF$4, 32-ROW()=Sheet1!$AG$4), 0, IF(COUNTIFS(Sheet1!$AK$2:$AK$51, COLUMN()-1, Sheet1!$AL$2:$AL$51, 32-ROW())>0, 99999, Sheet1!$AR$1*((COLUMN()-1-Sheet1!$AF$4)^2+(32-ROW()-Sheet1!$AG$4)^2) + Sheet1!$AR$2*SUMPRODUCT((Sheet1!$AK$2:$AK$51<>"")*(1/(((COLUMN()-1-Sheet1!$AK$2:$AK$51)^2+(32-ROW()-Sheet1!$AL$2:$AL$51)^2)+0.1)))))} -> 9843.2673 | ... AE7: {=IF(AND(COLUMN()-1=Sheet1!$AF$4, 32-ROW()=Sheet1!$AG$4), 0, IF(COUNTIFS(Sheet1!$AK$2:$AK$51, COLUMN()-1, Sheet1!$AL$2:$AL$51, 32-ROW())>0, 99999, Sheet1!$AR$1*((COLUMN()-1-Sheet1!$AF$4)^2+(32-ROW()-Sheet1!$AG$4)^2) + Sheet1!$AR$2*SUMPRODUCT((Sheet1!$AK$2:$AK$51<>"")*(1/(((COLUMN()-1-Sheet1!$AK$2:$AK$51)^2+(32-ROW()-Sheet1!$AL$2:$AL$51)^2)+0.1)))))} -> 1759.3557 | AF7: 99999
